Workbook
Name DevelopersList: Lists!$A$2:$A$50
Name MonthsList: Lists!$B$2:$B$13
Name ProjectsList: Projects!$A$2:$A$50
Name BlendRate: Lists!$G$1
Name Mandays: Lists!$G$2
Name DevRateTable: Lists!$A$3:$C$4

Sheet Instructions
A1: Yearly Project Plan Template (Sample)
A3: How to use:
A4: 1) Projects sheet: define each project's Start Month and End Month (Jan–Dec). StartIdx/EndIdx/Duration are calculated.
A5: 2) Allocations sheet: add one row per Developer–Project assignment. Choose Developer and Project from dropdowns.
A6: 3) Enter monthly effort as a fraction (0.00 to 1.00). You can only enter effort within the project's active months.
A7: • Outside active months: cell must be blank (validated) and is shaded grey.
A8: 4) Summary sheet: project totals by month + developer utilization by month (cells turn red if utilization is <1 or >1).
A9: Tip: Add more developers on the Lists sheet and more projects on the Projects sheet—dropdowns update automatically.

Sheet Lists
A1: Developers | B1: Months | F1: BlendRate | G1: 500 | L1: Mandays
A2: Developer | B2: Jan | C2: DailyRate | D2: RateRatio (Rate/Blend) | F2: Mandays | G2: 21 | L2: 20
A3: Dev 1 | B3: Feb | C3: 500 | D3: =C3/$G$1 | L3: 20
A4: Dev 2 | B4: Mar | C4: 600 | D4: =C4/$G$1 | L4: 20
B5: Apr | L5: 20
B6: May | L6: 20
B7: Jun | L7: 20
B8: Jul | L8: 20
B9: Aug | L9: 20
B10: Sep | L10: 20
B11: Oct | L11: 20
B12: Nov | L12: 20
B13: Dec | L13: 20
L14: 20
L15: 20
L16: 20
L17: 20
L18: 20
L19: 20
L20: 20
L21: 20
L22: 20
L23: 20
L24: 20
L25: 20
... L37: 20

Sheet Projects
A1: Project | B1: Start Month | C1: End Month | D1: StartIdx | E1: EndIdx | F1: Duration (months) | G1: Notes
A2: Project A | B2: Jan | C2: Mar | D2: =IFERROR(MATCH(B2,MonthsList,0),"") | E2: =IFERROR(MATCH(C2,MonthsList,0),"") | F2: =IF(AND(D2<>"",E2<>""),E2-D2+1,"") | G2: Example 3-month project
A3: Project B | B3: Jan | C3: May | D3: =IFERROR(MATCH(B3,MonthsList,0),"") | E3: =IFERROR(MATCH(C3,MonthsList,0),"") | F3: =IF(AND(D3<>"",E3<>""),E3-D3+1,"") | G3: Example 5-month project
A4: Project C | B4: Jan | C4: Feb | D4: =IFERROR(MATCH(B4,MonthsList,0),"") | E4: =IFERROR(MATCH(C4,MonthsList,0),"") | F4: =IF(AND(D4<>"",E4<>""),E4-D4+1,"") | G4: Example 2-month project
A5: Project D | B5: Jul | C5: Sep | D5: =IFERROR(MATCH(B2,MonthsList,0),"") | E5: =IFERROR(MATCH(C2,MonthsList,0),"") | F5: =IF(AND(D2<>"",E2<>""),E2-D2+1,"")
A6: Project E | B6: Oct | C6: Dec | D6: =IFERROR(MATCH(B2,MonthsList,0),"") | E6: =IFERROR(MATCH(C2,MonthsList,0),"") | F6: =IF(AND(D2<>"",E2<>""),E2-D2+1,"")
A7: Project F | B7: Aug | C7: Nov | D7: =IFERROR(MATCH(B2,MonthsList,0),"") | E7: =IFERROR(MATCH(C2,MonthsList,0),"") | F7: =IF(AND(D2<>"",E2<>""),E2-D2+1,"")
D8: =IFERROR(MATCH(B8,MonthsList,0),"") | E8: =IFERROR(MATCH(C8,MonthsList,0),"") | F8: =IF(AND(D8<>"",E8<>""),E8-D8+1,"")
D9: =IFERROR(MATCH(B9,MonthsList,0),"") | E9: =IFERROR(MATCH(C9,MonthsList,0),"") | F9: =IF(AND(D9<>"",E9<>""),E9-D9+1,"")
D10: =IFERROR(MATCH(B10,MonthsList,0),"") | E10: =IFERROR(MATCH(C10,MonthsList,0),"") | F10: =IF(AND(D10<>"",E10<>""),E10-D10+1,"")
D11: =IFERROR(MATCH(B11,MonthsList,0),"") | E11: =IFERROR(MATCH(C11,MonthsList,0),"") | F11: =IF(AND(D11<>"",E11<>""),E11-D11+1,"")
D12: =IFERROR(MATCH(B12,MonthsList,0),"") | E12: =IFERROR(MATCH(C12,MonthsList,0),"") | F12: =IF(AND(D12<>"",E12<>""),E12-D12+1,"")
D13: =IFERROR(MATCH(B13,MonthsList,0),"") | E13: =IFERROR(MATCH(C13,MonthsList,0),"") | F13: =IF(AND(D13<>"",E13<>""),E13-D13+1,"")
D14: =IFERROR(MATCH(B14,MonthsList,0),"") | E14: =IFERROR(MATCH(C14,MonthsList,0),"") | F14: =IF(AND(D14<>"",E14<>""),E14-D14+1,"")
D15: =IFERROR(MATCH(B15,MonthsList,0),"") | E15: =IFERROR(MATCH(C15,MonthsList,0),"") | F15: =IF(AND(D15<>"",E15<>""),E15-D15+1,"")
D16: =IFERROR(MATCH(B16,MonthsList,0),"") | E16: =IFERROR(MATCH(C16,MonthsList,0),"") | F16: =IF(AND(D16<>"",E16<>""),E16-D16+1,"")
D17: =IFERROR(MATCH(B17,MonthsList,0),"") | E17: =IFERROR(MATCH(C17,MonthsList,0),"") | F17: =IF(AND(D17<>"",E17<>""),E17-D17+1,"")
D18: =IFERROR(MATCH(B18,MonthsList,0),"") | E18: =IFERROR(MATCH(C18,MonthsList,0),"") | F18: =IF(AND(D18<>"",E18<>""),E18-D18+1,"")
D19: =IFERROR(MATCH(B19,MonthsList,0),"") | E19: =IFERROR(MATCH(C19,MonthsList,0),"") | F19: =IF(AND(D19<>"",E19<>""),E19-D19+1,"")
... D25: =IFERROR(MATCH(B25,MonthsList,0),"") | E25: =IFERROR(MATCH(C25,MonthsList,0),"") | F25: =IF(AND(D25<>"",E25<>""),E25-D25+1,"")

Sheet Allocations
H1: 1 | I1: 2 | J1: 3 | K1: 4 | L1: 5 | M1: 6 | N1: 7 | O1: 8 | P1: 9 | Q1: 10 | R1: 11 | S1: 12
A2: Developer | B2: Project | C2: Start Month | D2: End Month | E2: StartIdx | F2: EndIdx | G2: Row Total | H2: Jan | I2: Feb | J2: Mar | K2: Apr | L2: May | M2: Jun | N2: Jul | O2: Aug | P2: Sep | Q2: Oct | R2: Nov | S2: Dec | T2: DevRate | U2: Feb Cost | V2: Mar Cost | W2: Apr Cost | X2: May Cost | Y2: Jun Cost | Z2: Jul Cost | AA2: Aug Cost | AB2: Sep Cost | AC2: Oct Cost | AD2: Nov Cost | AE2: Dec Cost
A3: Dev 1 | B3: Project A | C3: =IFERROR(VLOOKUP($B3,Projects!$A$2:$G$50,2,FALSE),"") | D3: =IFERROR(VLOOKUP($B3,Projects!$A$2:$G$50,3,FALSE),"") | E3: =IFERROR(VLOOKUP($B3,Projects!$A$2:$G$50,4,FALSE),"") | F3: =IFERROR(VLOOKUP($B3,Projects!$A$2:$G$50,5,FALSE),"") | G3: =SUM(H3:S3) | H3: 0.5 | I3: 0.25 | J3: 0.25 | T3: =IF($A3="","",VLOOKUP($A3,DevRateTable,3,FALSE)) | U3: =IF(I3="","",I3*IFERROR(VLOOKUP($A3&"|Feb",Lists!$J:$L,2,FALSE),0)*IFERROR(VLOOKUP($A3&"|Feb",Lists!$J:$L,3,FALSE),0)) | V3: =IF(J3="","",J3*IFERROR(VLOOKUP($A3&"|Mar",Lists!$J:$L,2,FALSE),0)*IFERROR(VLOOKUP($A3&"|Mar",Lists!$J:$L,3,FALSE),0)) | W3: =IF(K3="","",K3*IFERROR(VLOOKUP($A3&"|Apr",Lists!$J:$L,2,FALSE),0)*IFERROR(VLOOKUP($A3&"|Apr",Lists!$J:$L,3,FALSE),0)) | X3: =IF(L3="","",L3*IFERROR(VLOOKUP($A3&"|May",Lists!$J:$L,2,FALSE),0)*IFERROR(VLOOKUP($A3&"|May",Lists!$J:$L,3,FALSE),0)) | Y3: =IF(M3="","",M3*IFERROR(VLOOKUP($A3&"|Jun",Lists!$J:$L,2,FALSE),0)*IFERROR(VLOOKUP($A3&"|Jun",Lists!$J:$L,3,FALSE),0)) | Z3: =IF(N3="","",N3*IFERROR(VLOOKUP($A3&"|Jul",Lists!$J:$L,2,FALSE),0)*IFERROR(VLOOKUP($A3&"|Jul",Lists!$J:$L,3,FALSE),0)) | AA3: =IF(O3="","",O3*IFERROR(VLOOKUP($A3&"|Aug",Lists!$J:$L,2,FALSE),0)*IFERROR(VLOOKUP($A3&"|Aug",Lists!$J:$L,3,FALSE),0)) | AB3: =IF(P3="","",P3*IFERROR(VLOOKUP($A3&"|Sep",Lists!$J:$L,2,FALSE),0)*IFERROR(VLOOKUP($A3&"|Sep",Lists!$J:$L,3,FALSE),0)) | AC3: =IF(Q3="","",Q3*IFERROR(VLOOKUP($A3&"|Oct",Lists!$J:$L,2,FALSE),0)*IFERROR(VLOOKUP($A3&"|Oct",Lists!$J:$L,3,FALSE),0)) | AD3: =IF(R3="","",R3*IFERROR(VLOOKUP($A3&"|Nov",Lists!$J:$L,2,FALSE),0)*IFERROR(VLOOKUP($A3&"|Nov",Lists!$J:$L,3,FALSE),0)) | AE3: =IF(S3="","",S3*IFERROR(VLOOKUP($A3&"|Dec",Lists!$J:$L,2,FALSE),0)*IFERROR(VLOOKUP($A3&"|Dec",Lists!$J:$L,3,FALSE),0))
A4: Dev 1 | B4: Project B | C4: =IFERROR(VLOOKUP($B4,Projects!$A$2:$G$50,2,FALSE),"") | D4: =IFERROR(VLOOKUP($B4,Projects!$A$2:$G$50,3,FALSE),"") | E4: =IFERROR(VLOOKUP($B4,Projects!$A$2:$G$50,4,FALSE),"") | F4: =IFERROR(VLOOKUP($B4,Projects!$A$2:$G$50,5,FALSE),"") | G4: =SUM(H4:S4) | H4: 0.25 | I4: 0.25 | J4: 0.25 | K4: 0.5 | L4: 0.5 | T4: =IF($A4="","",VLOOKUP($A4,DevRateTable,3,FALSE)) | U4: =IF(I4="","",I4*IFERROR(VLOOKUP($A4&"|Feb",Lists!$J:$L,2,FALSE),0)*IFERROR(VLOOKUP($A4&"|Feb",Lists!$J:$L,3,FALSE),0)) | V4: =IF(J4="","",J4*IFERROR(VLOOKUP($A4&"|Mar",Lists!$J:$L,2,FALSE),0)*IFERROR(VLOOKUP($A4&"|Mar",Lists!$J:$L,3,FALSE),0)) | W4: =IF(K4="","",K4*IFERROR(VLOOKUP($A4&"|Apr",Lists!$J:$L,2,FALSE),0)*IFERROR(VLOOKUP($A4&"|Apr",Lists!$J:$L,3,FALSE),0)) | X4: =IF(L4="","",L4*IFERROR(VLOOKUP($A4&"|May",Lists!$J:$L,2,FALSE),0)*IFERROR(VLOOKUP($A4&"|May",Lists!$J:$L,3,FALSE),0)) | Y4: =IF(M4="","",M4*IFERROR(VLOOKUP($A4&"|Jun",Lists!$J:$L,2,FALSE),0)*IFERROR(VLOOKUP($A4&"|Jun",Lists!$J:$L,3,FALSE),0)) | Z4: =IF(N4="","",N4*IFERROR(VLOOKUP($A4&"|Jul",Lists!$J:$L,2,FALSE),0)*IFERROR(VLOOKUP($A4&"|Jul",Lists!$J:$L,3,FALSE),0)) | AA4: =IF(O4="","",O4*IFERROR(VLOOKUP($A4&"|Aug",Lists!$J:$L,2,FALSE),0)*IFERROR(VLOOKUP($A4&"|Aug",Lists!$J:$L,3,FALSE),0)) | AB4: =IF(P4="","",P4*IFERROR(VLOOKUP($A4&"|Sep",Lists!$J:$L,2,FALSE),0)*IFERROR(VLOOKUP($A4&"|Sep",Lists!$J:$L,3,FALSE),0)) | AC4: =IF(Q4="","",Q4*IFERROR(VLOOKUP($A4&"|Oct",Lists!$J:$L,2,FALSE),0)*IFERROR(VLOOKUP($A4&"|Oct",Lists!$J:$L,3,FALSE),0)) | AD4: =IF(R4="","",R4*IFERROR(VLOOKUP($A4&"|Nov",Lists!$J:$L,2,FALSE),0)*IFERROR(VLOOKUP($A4&"|Nov",Lists!$J:$L,3,FALSE),0)) | AE4: =IF(S4="","",S4*IFERROR(VLOOKUP($A4&"|Dec",Lists!$J:$L,2,FALSE),0)*IFERROR(VLOOKUP($A4&"|Dec",Lists!$J:$L,3,FALSE),0))
A5: Dev 2 | B5: Project A | C5: =IFERROR(VLOOKUP($B5,Projects!$A$2:$G$50,2,FALSE),"") | D5: =IFERROR(VLOOKUP($B5,Projects!$A$2:$G$50,3,FALSE),"") | E5: =IFERROR(VLOOKUP($B5,Projects!$A$2:$G$50,4,FALSE),"") | F5: =IFERROR(VLOOKUP($B5,Projects!$A$2:$G$50,5,FALSE),"") | G5: =SUM(H5:S5) | I5: 0.5 | J5: 0.5 | T5: =IF($A5="","",VLOOKUP($A5,DevRateTable,3,FALSE)) | U5: =IF(I5="","",I5*IFERROR(VLOOKUP($A5&"|Feb",Lists!$J:$L,2,FALSE),0)*IFERROR(VLOOKUP($A5&"|Feb",Lists!$J:$L,3,FALSE),0)) | V5: =IF(J5="","",J5*IFERROR(VLOOKUP($A5&"|Mar",Lists!$J:$L,2,FALSE),0)*IFERROR(VLOOKUP($A5&"|Mar",Lists!$J:$L,3,FALSE),0)) | W5: =IF(K5="","",K5*IFERROR(VLOOKUP($A5&"|Apr",Lists!$J:$L,2,FALSE),0)*IFERROR(VLOOKUP($A5&"|Apr",Lists!$J:$L,3,FALSE),0)) | X5: =IF(L5="","",L5*IFERROR(VLOOKUP($A5&"|May",Lists!$J:$L,2,FALSE),0)*IFERROR(VLOOKUP($A5&"|May",Lists!$J:$L,3,FALSE),0)) | Y5: =IF(M5="","",M5*IFERROR(VLOOKUP($A5&"|Jun",Lists!$J:$L,2,FALSE),0)*IFERROR(VLOOKUP($A5&"|Jun",Lists!$J:$L,3,FALSE),0)) | Z5: =IF(N5="","",N5*IFERROR(VLOOKUP($A5&"|Jul",Lists!$J:$L,2,FALSE),0)*IFERROR(VLOOKUP($A5&"|Jul",Lists!$J:$L,3,FALSE),0)) | AA5: =IF(O5="","",O5*IFERROR(VLOOKUP($A5&"|Aug",Lists!$J:$L,2,FALSE),0)*IFERROR(VLOOKUP($A5&"|Aug",Lists!$J:$L,3,FALSE),0)) | AB5: =IF(P5="","",P5*IFERROR(VLOOKUP($A5&"|Sep",Lists!$J:$L,2,FALSE),0)*IFERROR(VLOOKUP($A5&"|Sep",Lists!$J:$L,3,FALSE),0)) | AC5: =IF(Q5="","",Q5*IFERROR(VLOOKUP($A5&"|Oct",Lists!$J:$L,2,FALSE),0)*IFERROR(VLOOKUP($A5&"|Oct",Lists!$J:$L,3,FALSE),0)) | AD5: =IF(R5="","",R5*IFERROR(VLOOKUP($A5&"|Nov",Lists!$J:$L,2,FALSE),0)*IFERROR(VLOOKUP($A5&"|Nov",Lists!$J:$L,3,FALSE),0)) | AE5: =IF(S5="","",S5*IFERROR(VLOOKUP($A5&"|Dec",Lists!$J:$L,2,FALSE),0)*IFERROR(VLOOKUP($A5&"|Dec",Lists!$J:$L,3,FALSE),0))
A6: Dev 2 | B6: Project C | C6: =IFERROR(VLOOKUP($B6,Projects!$A$2:$G$50,2,FALSE),"") | D6: =IFERROR(VLOOKUP($B6,Projects!$A$2:$G$50,3,FALSE),"") | E6: =IFERROR(VLOOKUP($B6,Projects!$A$2:$G$50,4,FALSE),"") | F6: =IFERROR(VLOOKUP($B6,Projects!$A$2:$G$50,5,FALSE),"") | G6: =SUM(H6:S6) | H6: 0.5 | I6: 0.5 | T6: =IF($A6="","",VLOOKUP($A6,DevRateTable,3,FALSE)) | U6: =IF(I6="","",I6*IFERROR(VLOOKUP($A6&"|Feb",Lists!$J:$L,2,FALSE),0)*IFERROR(VLOOKUP($A6&"|Feb",Lists!$J:$L,3,FALSE),0)) | V6: =IF(J6="","",J6*IFERROR(VLOOKUP($A6&"|Mar",Lists!$J:$L,2,FALSE),0)*IFERROR(VLOOKUP($A6&"|Mar",Lists!$J:$L,3,FALSE),0)) | W6: =IF(K6="","",K6*IFERROR(VLOOKUP($A6&"|Apr",Lists!$J:$L,2,FALSE),0)*IFERROR(VLOOKUP($A6&"|Apr",Lists!$J:$L,3,FALSE),0)) | X6: =IF(L6="","",L6*IFERROR(VLOOKUP($A6&"|May",Lists!$J:$L,2,FALSE),0)*IFERROR(VLOOKUP($A6&"|May",Lists!$J:$L,3,FALSE),0)) | Y6: =IF(M6="","",M6*IFERROR(VLOOKUP($A6&"|Jun",Lists!$J:$L,2,FALSE),0)*IFERROR(VLOOKUP($A6&"|Jun",Lists!$J:$L,3,FALSE),0)) | Z6: =IF(N6="","",N6*IFERROR(VLOOKUP($A6&"|Jul",Lists!$J:$L,2,FALSE),0)*IFERROR(VLOOKUP($A6&"|Jul",Lists!$J:$L,3,FALSE),0)) | AA6: =IF(O6="","",O6*IFERROR(VLOOKUP($A6&"|Aug",Lists!$J:$L,2,FALSE),0)*IFERROR(VLOOKUP($A6&"|Aug",Lists!$J:$L,3,FALSE),0)) | AB6: =IF(P6="","",P6*IFERROR(VLOOKUP($A6&"|Sep",Lists!$J:$L,2,FALSE),0)*IFERROR(VLOOKUP($A6&"|Sep",Lists!$J:$L,3,FALSE),0)) | AC6: =IF(Q6="","",Q6*IFERROR(VLOOKUP($A6&"|Oct",Lists!$J:$L,2,FALSE),0)*IFERROR(VLOOKUP($A6&"|Oct",Lists!$J:$L,3,FALSE),0)) | AD6: =IF(R6="","",R6*IFERROR(VLOOKUP($A6&"|Nov",Lists!$J:$L,2,FALSE),0)*IFERROR(VLOOKUP($A6&"|Nov",Lists!$J:$L,3,FALSE),0)) | AE6: =IF(S6="","",S6*IFERROR(VLOOKUP($A6&"|Dec",Lists!$J:$L,2,FALSE),0)*IFERROR(VLOOKUP($A6&"|Dec",Lists!$J:$L,3,FALSE),0))
A7: Dev 1 | B7: Project D | C7: Jul | D7: Sep | E7: =IFERROR(VLOOKUP($B3,Projects!$A$2:$G$50,4,FALSE),"") | F7: =IFERROR(VLOOKUP($B3,Projects!$A$2:$G$50,5,FALSE),"") | G7: =SUM(H7:S7) | N7: 0.5 | O7: 0.75 | P7: 0.5 | T7: =IF($A7="","",VLOOKUP($A7,DevRateTable,3,FALSE)) | U7: =IF(I7="","",I7*IFERROR(VLOOKUP($A7&"|Feb",Lists!$J:$L,2,FALSE),0)*IFERROR(VLOOKUP($A7&"|Feb",Lists!$J:$L,3,FALSE),0)) | V7: =IF(J7="","",J7*IFERROR(VLOOKUP($A7&"|Mar",Lists!$J:$L,2,FALSE),0)*IFERROR(VLOOKUP($A7&"|Mar",Lists!$J:$L,3,FALSE),0)) | W7: =IF(K7="","",K7*IFERROR(VLOOKUP($A7&"|Apr",Lists!$J:$L,2,FALSE),0)*IFERROR(VLOOKUP($A7&"|Apr",Lists!$J:$L,3,FALSE),0)) | X7: =IF(L7="","",L7*IFERROR(VLOOKUP($A7&"|May",Lists!$J:$L,2,FALSE),0)*IFERROR(VLOOKUP($A7&"|May",Lists!$J:$L,3,FALSE),0)) | Y7: =IF(M7="","",M7*IFERROR(VLOOKUP($A7&"|Jun",Lists!$J:$L,2,FALSE),0)*IFERROR(VLOOKUP($A7&"|Jun",Lists!$J:$L,3,FALSE),0)) | Z7: =IF(N7="","",N7*IFERROR(VLOOKUP($A7&"|Jul",Lists!$J:$L,2,FALSE),0)*IFERROR(VLOOKUP($A7&"|Jul",Lists!$J:$L,3,FALSE),0)) | AA7: =IF(O7="","",O7*IFERROR(VLOOKUP($A7&"|Aug",Lists!$J:$L,2,FALSE),0)*IFERROR(VLOOKUP($A7&"|Aug",Lists!$J:$L,3,FALSE),0)) | AB7: =IF(P7="","",P7*IFERROR(VLOOKUP($A7&"|Sep",Lists!$J:$L,2,FALSE),0)*IFERROR(VLOOKUP($A7&"|Sep",Lists!$J:$L,3,FALSE),0)) | AC7: =IF(Q7="","",Q7*IFERROR(VLOOKUP($A7&"|Oct",Lists!$J:$L,2,FALSE),0)*IFERROR(VLOOKUP($A7&"|Oct",Lists!$J:$L,3,FALSE),0)) | AD7: =IF(R7="","",R7*IFERROR(VLOOKUP($A7&"|Nov",Lists!$J:$L,2,FALSE),0)*IFERROR(VLOOKUP($A7&"|Nov",Lists!$J:$L,3,FALSE),0)) | AE7: =IF(S7="","",S7*IFERROR(VLOOKUP($A7&"|Dec",Lists!$J:$L,2,FALSE),0)*IFERROR(VLOOKUP($A7&"|Dec",Lists!$J:$L,3,FALSE),0))
A8: Dev 1 | B8: Project F | C8: Aug | D8: Nov | E8: =IFERROR(VLOOKUP($B3,Projects!$A$2:$G$50,4,FALSE),"") | F8: =IFERROR(VLOOKUP($B3,Projects!$A$2:$G$50,5,FALSE),"") | G8: =SUM(H8:S8) | O8: 0.5 | P8: 0.5 | Q8: 0.25 | R8: 0.5 | T8: =IF($A8="","",VLOOKUP($A8,DevRateTable,3,FALSE)) | U8: =IF(I8="","",I8*IFERROR(VLOOKUP($A8&"|Feb",Lists!$J:$L,2,FALSE),0)*IFERROR(VLOOKUP($A8&"|Feb",Lists!$J:$L,3,FALSE),0)) | V8: =IF(J8="","",J8*IFERROR(VLOOKUP($A8&"|Mar",Lists!$J:$L,2,FALSE),0)*IFERROR(VLOOKUP($A8&"|Mar",Lists!$J:$L,3,FALSE),0)) | W8: =IF(K8="","",K8*IFERROR(VLOOKUP($A8&"|Apr",Lists!$J:$L,2,FALSE),0)*IFERROR(VLOOKUP($A8&"|Apr",Lists!$J:$L,3,FALSE),0)) | X8: =IF(L8="","",L8*IFERROR(VLOOKUP($A8&"|May",Lists!$J:$L,2,FALSE),0)*IFERROR(VLOOKUP($A8&"|May",Lists!$J:$L,3,FALSE),0)) | Y8: =IF(M8="","",M8*IFERROR(VLOOKUP($A8&"|Jun",Lists!$J:$L,2,FALSE),0)*IFERROR(VLOOKUP($A8&"|Jun",Lists!$J:$L,3,FALSE),0)) | Z8: =IF(N8="","",N8*IFERROR(VLOOKUP($A8&"|Jul",Lists!$J:$L,2,FALSE),0)*IFERROR(VLOOKUP($A8&"|Jul",Lists!$J:$L,3,FALSE),0)) | AA8: =IF(O8="","",O8*IFERROR(VLOOKUP($A8&"|Aug",Lists!$J:$L,2,FALSE),0)*IFERROR(VLOOKUP($A8&"|Aug",Lists!$J:$L,3,FALSE),0)) | AB8: =IF(P8="","",P8*IFERROR(VLOOKUP($A8&"|Sep",Lists!$J:$L,2,FALSE),0)*IFERROR(VLOOKUP($A8&"|Sep",Lists!$J:$L,3,FALSE),0)) | AC8: =IF(Q8="","",Q8*IFERROR(VLOOKUP($A8&"|Oct",Lists!$J:$L,2,FALSE),0)*IFERROR(VLOOKUP($A8&"|Oct",Lists!$J:$L,3,FALSE),0)) | AD8: =IF(R8="","",R8*IFERROR(VLOOKUP($A8&"|Nov",Lists!$J:$L,2,FALSE),0)*IFERROR(VLOOKUP($A8&"|Nov",Lists!$J:$L,3,FALSE),0)) | AE8: =IF(S8="","",S8*IFERROR(VLOOKUP($A8&"|Dec",Lists!$J:$L,2,FALSE),0)*IFERROR(VLOOKUP($A8&"|Dec",Lists!$J:$L,3,FALSE),0))
A9: Dev 2 | B9: Project E | C9: Oct | D9: Dec | E9: =IFERROR(VLOOKUP($B3,Projects!$A$2:$G$50,4,FALSE),"") | F9: =IFERROR(VLOOKUP($B3,Projects!$A$2:$G$50,5,FALSE),"") | G9: =SUM(H9:S9) | Q9: 0.75 | R9: 0.5 | S9: 1 | T9: =IF($A9="","",VLOOKUP($A9,DevRateTable,3,FALSE)) | U9: =IF(I9="","",I9*IFERROR(VLOOKUP($A9&"|Feb",Lists!$J:$L,2,FALSE),0)*IFERROR(VLOOKUP($A9&"|Feb",Lists!$J:$L,3,FALSE),0)) | V9: =IF(J9="","",J9*IFERROR(VLOOKUP($A9&"|Mar",Lists!$J:$L,2,FALSE),0)*IFERROR(VLOOKUP($A9&"|Mar",Lists!$J:$L,3,FALSE),0)) | W9: =IF(K9="","",K9*IFERROR(VLOOKUP($A9&"|Apr",Lists!$J:$L,2,FALSE),0)*IFERROR(VLOOKUP($A9&"|Apr",Lists!$J:$L,3,FALSE),0)) | X9: =IF(L9="","",L9*IFERROR(VLOOKUP($A9&"|May",Lists!$J:$L,2,FALSE),0)*IFERROR(VLOOKUP($A9&"|May",Lists!$J:$L,3,FALSE),0)) | Y9: =IF(M9="","",M9*IFERROR(VLOOKUP($A9&"|Jun",Lists!$J:$L,2,FALSE),0)*IFERROR(VLOOKUP($A9&"|Jun",Lists!$J:$L,3,FALSE),0)) | Z9: =IF(N9="","",N9*IFERROR(VLOOKUP($A9&"|Jul",Lists!$J:$L,2,FALSE),0)*IFERROR(VLOOKUP($A9&"|Jul",Lists!$J:$L,3,FALSE),0)) | AA9: =IF(O9="","",O9*IFERROR(VLOOKUP($A9&"|Aug",Lists!$J:$L,2,FALSE),0)*IFERROR(VLOOKUP($A9&"|Aug",Lists!$J:$L,3,FALSE),0)) | AB9: =IF(P9="","",P9*IFERROR(VLOOKUP($A9&"|Sep",Lists!$J:$L,2,FALSE),0)*IFERROR(VLOOKUP($A9&"|Sep",Lists!$J:$L,3,FALSE),0)) | AC9: =IF(Q9="","",Q9*IFERROR(VLOOKUP($A9&"|Oct",Lists!$J:$L,2,FALSE),0)*IFERROR(VLOOKUP($A9&"|Oct",Lists!$J:$L,3,FALSE),0)) | AD9: =IF(R9="","",R9*IFERROR(VLOOKUP($A9&"|Nov",Lists!$J:$L,2,FALSE),0)*IFERROR(VLOOKUP($A9&"|Nov",Lists!$J:$L,3,FALSE),0)) | AE9: =IF(S9="","",S9*IFERROR(VLOOKUP($A9&"|Dec",Lists!$J:$L,2,FALSE),0)*IFERROR(VLOOKUP($A9&"|Dec",Lists!$J:$L,3,FALSE),0))
A10: Dev 2 | B10: Project F | C10: Aug | D10: Nov | E10: =IFERROR(VLOOKUP($B3,Projects!$A$2:$G$50,4,FALSE),"") | F10: =IFERROR(VLOOKUP($B3,Projects!$A$2:$G$50,5,FALSE),"") | G10: =SUM(H10:S10) | O10: 0.25 | P10: 0.25 | Q10: 0.5 | R10: 0.75 | T10: =IF($A10="","",VLOOKUP($A10,DevRateTable,3,FALSE)) | U10: =IF(I10="","",I10*IFERROR(VLOOKUP($A10&"|Feb",Lists!$J:$L,2,FALSE),0)*IFERROR(VLOOKUP($A10&"|Feb",Lists!$J:$L,3,FALSE),0)) | V10: =IF(J10="","",J10*IFERROR(VLOOKUP($A10&"|Mar",Lists!$J:$L,2,FALSE),0)*IFERROR(VLOOKUP($A10&"|Mar",Lists!$J:$L,3,FALSE),0)) | W10: =IF(K10="","",K10*IFERROR(VLOOKUP($A10&"|Apr",Lists!$J:$L,2,FALSE),0)*IFERROR(VLOOKUP($A10&"|Apr",Lists!$J:$L,3,FALSE),0)) | X10: =IF(L10="","",L10*IFERROR(VLOOKUP($A10&"|May",Lists!$J:$L,2,FALSE),0)*IFERROR(VLOOKUP($A10&"|May",Lists!$J:$L,3,FALSE),0)) | Y10: =IF(M10="","",M10*IFERROR(VLOOKUP($A10&"|Jun",Lists!$J:$L,2,FALSE),0)*IFERROR(VLOOKUP($A10&"|Jun",Lists!$J:$L,3,FALSE),0)) | Z10: =IF(N10="","",N10*IFERROR(VLOOKUP($A10&"|Jul",Lists!$J:$L,2,FALSE),0)*IFERROR(VLOOKUP($A10&"|Jul",Lists!$J:$L,3,FALSE),0)) | AA10: =IF(O10="","",O10*IFERROR(VLOOKUP($A10&"|Aug",Lists!$J:$L,2,FALSE),0)*IFERROR(VLOOKUP($A10&"|Aug",Lists!$J:$L,3,FALSE),0)) | AB10: =IF(P10="","",P10*IFERROR(VLOOKUP($A10&"|Sep",Lists!$J:$L,2,FALSE),0)*IFERROR(VLOOKUP($A10&"|Sep",Lists!$J:$L,3,FALSE),0)) | AC10: =IF(Q10="","",Q10*IFERROR(VLOOKUP($A10&"|Oct",Lists!$J:$L,2,FALSE),0)*IFERROR(VLOOKUP($A10&"|Oct",Lists!$J:$L,3,FALSE),0)) | AD10: =IF(R10="","",R10*IFERROR(VLOOKUP($A10&"|Nov",Lists!$J:$L,2,FALSE),0)*IFERROR(VLOOKUP($A10&"|Nov",Lists!$J:$L,3,FALSE),0)) | AE10: =IF(S10="","",S10*IFERROR(VLOOKUP($A10&"|Dec",Lists!$J:$L,2,FALSE),0)*IFERROR(VLOOKUP($A10&"|Dec",Lists!$J:$L,3,FALSE),0))
C11: =IFERROR(VLOOKUP($B11,Projects!$A$2:$G$50,2,FALSE),"") | D11: =IFERROR(VLOOKUP($B11,Projects!$A$2:$G$50,3,FALSE),"") | E11: =IFERROR(VLOOKUP($B11,Projects!$A$2:$G$50,4,FALSE),"") | F11: =IFERROR(VLOOKUP($B11,Projects!$A$2:$G$50,5,FALSE),"") | G11: =SUM(H11:S11) | T11: =IF($A11="","",VLOOKUP($A11,DevRateTable,3,FALSE)) | U11: =IF(I11="","",I11*IFERROR(VLOOKUP($A11&"|Feb",Lists!$J:$L,2,FALSE),0)*IFERROR(VLOOKUP($A11&"|Feb",Lists!$J:$L,3,FALSE),0)) | V11: =IF(J11="","",J11*IFERROR(VLOOKUP($A11&"|Mar",Lists!$J:$L,2,FALSE),0)*IFERROR(VLOOKUP($A11&"|Mar",Lists!$J:$L,3,FALSE),0)) | W11: =IF(K11="","",K11*IFERROR(VLOOKUP($A11&"|Apr",Lists!$J:$L,2,FALSE),0)*IFERROR(VLOOKUP($A11&"|Apr",Lists!$J:$L,3,FALSE),0)) | X11: =IF(L11="","",L11*IFERROR(VLOOKUP($A11&"|May",Lists!$J:$L,2,FALSE),0)*IFERROR(VLOOKUP($A11&"|May",Lists!$J:$L,3,FALSE),0)) | Y11: =IF(M11="","",M11*IFERROR(VLOOKUP($A11&"|Jun",Lists!$J:$L,2,FALSE),0)*IFERROR(VLOOKUP($A11&"|Jun",Lists!$J:$L,3,FALSE),0)) | Z11: =IF(N11="","",N11*IFERROR(VLOOKUP($A11&"|Jul",Lists!$J:$L,2,FALSE),0)*IFERROR(VLOOKUP($A11&"|Jul",Lists!$J:$L,3,FALSE),0)) | AA11: =IF(O11="","",O11*IFERROR(VLOOKUP($A11&"|Aug",Lists!$J:$L,2,FALSE),0)*IFERROR(VLOOKUP($A11&"|Aug",Lists!$J:$L,3,FALSE),0)) | AB11: =IF(P11="","",P11*IFERROR(VLOOKUP($A11&"|Sep",Lists!$J:$L,2,FALSE),0)*IFERROR(VLOOKUP($A11&"|Sep",Lists!$J:$L,3,FALSE),0)) | AC11: =IF(Q11="","",Q11*IFERROR(VLOOKUP($A11&"|Oct",Lists!$J:$L,2,FALSE),0)*IFERROR(VLOOKUP($A11&"|Oct",Lists!$J:$L,3,FALSE),0)) | AD11: =IF(R11="","",R11*IFERROR(VLOOKUP($A11&"|Nov",Lists!$J:$L,2,FALSE),0)*IFERROR(VLOOKUP($A11&"|Nov",Lists!$J:$L,3,FALSE),0)) | AE11: =IF(S11="","",S11*IFERROR(VLOOKUP($A11&"|Dec",Lists!$J:$L,2,FALSE),0)*IFERROR(VLOOKUP($A11&"|Dec",Lists!$J:$L,3,FALSE),0))
C12: =IFERROR(VLOOKUP($B12,Projects!$A$2:$G$50,2,FALSE),"") | D12: =IFERROR(VLOOKUP($B12,Projects!$A$2:$G$50,3,FALSE),"") | E12: =IFERROR(VLOOKUP($B12,Projects!$A$2:$G$50,4,FALSE),"") | F12: =IFERROR(VLOOKUP($B12,Projects!$A$2:$G$50,5,FALSE),"") | G12: =SUM(H12:S12) | T12: =IF($A12="","",VLOOKUP($A12,DevRateTable,3,FALSE)) | U12: =IF(I12="","",I12*IFERROR(VLOOKUP($A12&"|Feb",Lists!$J:$L,2,FALSE),0)*IFERROR(VLOOKUP($A12&"|Feb",Lists!$J:$L,3,FALSE),0)) | V12: =IF(J12="","",J12*IFERROR(VLOOKUP($A12&"|Mar",Lists!$J:$L,2,FALSE),0)*IFERROR(VLOOKUP($A12&"|Mar",Lists!$J:$L,3,FALSE),0)) | W12: =IF(K12="","",K12*IFERROR(VLOOKUP($A12&"|Apr",Lists!$J:$L,2,FALSE),0)*IFERROR(VLOOKUP($A12&"|Apr",Lists!$J:$L,3,FALSE),0)) | X12: =IF(L12="","",L12*IFERROR(VLOOKUP($A12&"|May",Lists!$J:$L,2,FALSE),0)*IFERROR(VLOOKUP($A12&"|May",Lists!$J:$L,3,FALSE),0)) | Y12: =IF(M12="","",M12*IFERROR(VLOOKUP($A12&"|Jun",Lists!$J:$L,2,FALSE),0)*IFERROR(VLOOKUP($A12&"|Jun",Lists!$J:$L,3,FALSE),0)) | Z12: =IF(N12="","",N12*IFERROR(VLOOKUP($A12&"|Jul",Lists!$J:$L,2,FALSE),0)*IFERROR(VLOOKUP($A12&"|Jul",Lists!$J:$L,3,FALSE),0)) | AA12: =IF(O12="","",O12*IFERROR(VLOOKUP($A12&"|Aug",Lists!$J:$L,2,FALSE),0)*IFERROR(VLOOKUP($A12&"|Aug",Lists!$J:$L,3,FALSE),0)) | AB12: =IF(P12="","",P12*IFERROR(VLOOKUP($A12&"|Sep",Lists!$J:$L,2,FALSE),0)*IFERROR(VLOOKUP($A12&"|Sep",Lists!$J:$L,3,FALSE),0)) | AC12: =IF(Q12="","",Q12*IFERROR(VLOOKUP($A12&"|Oct",Lists!$J:$L,2,FALSE),0)*IFERROR(VLOOKUP($A12&"|Oct",Lists!$J:$L,3,FALSE),0)) | AD12: =IF(R12="","",R12*IFERROR(VLOOKUP($A12&"|Nov",Lists!$J:$L,2,FALSE),0)*IFERROR(VLOOKUP($A12&"|Nov",Lists!$J:$L,3,FALSE),0)) | AE12: =IF(S12="","",S12*IFERROR(VLOOKUP($A12&"|Dec",Lists!$J:$L,2,FALSE),0)*IFERROR(VLOOKUP($A12&"|Dec",Lists!$J:$L,3,FALSE),0))
C13: =IFERROR(VLOOKUP($B13,Projects!$A$2:$G$50,2,FALSE),"") | D13: =IFERROR(VLOOKUP($B13,Projects!$A$2:$G$50,3,FALSE),"") | E13: =IFERROR(VLOOKUP($B13,Projects!$A$2:$G$50,4,FALSE),"") | F13: =IFERROR(VLOOKUP($B13,Projects!$A$2:$G$50,5,FALSE),"") | G13: =SUM(H13:S13) | T13: =IF($A13="","",VLOOKUP($A13,DevRateTable,3,FALSE)) | U13: =IF(I13="","",I13*IFERROR(VLOOKUP($A13&"|Feb",Lists!$J:$L,2,FALSE),0)*IFERROR(VLOOKUP($A13&"|Feb",Lists!$J:$L,3,FALSE),0)) | V13: =IF(J13="","",J13*IFERROR(VLOOKUP($A13&"|Mar",Lists!$J:$L,2,FALSE),0)*IFERROR(VLOOKUP($A13&"|Mar",Lists!$J:$L,3,FALSE),0)) | W13: =IF(K13="","",K13*IFERROR(VLOOKUP($A13&"|Apr",Lists!$J:$L,2,FALSE),0)*IFERROR(VLOOKUP($A13&"|Apr",Lists!$J:$L,3,FALSE),0)) | X13: =IF(L13="","",L13*IFERROR(VLOOKUP($A13&"|May",Lists!$J:$L,2,FALSE),0)*IFERROR(VLOOKUP($A13&"|May",Lists!$J:$L,3,FALSE),0)) | Y13: =IF(M13="","",M13*IFERROR(VLOOKUP($A13&"|Jun",Lists!$J:$L,2,FALSE),0)*IFERROR(VLOOKUP($A13&"|Jun",Lists!$J:$L,3,FALSE),0)) | Z13: =IF(N13="","",N13*IFERROR(VLOOKUP($A13&"|Jul",Lists!$J:$L,2,FALSE),0)*IFERROR(VLOOKUP($A13&"|Jul",Lists!$J:$L,3,FALSE),0)) | AA13: =IF(O13="","",O13*IFERROR(VLOOKUP($A13&"|Aug",Lists!$J:$L,2,FALSE),0)*IFERROR(VLOOKUP($A13&"|Aug",Lists!$J:$L,3,FALSE),0)) | AB13: =IF(P13="","",P13*IFERROR(VLOOKUP($A13&"|Sep",Lists!$J:$L,2,FALSE),0)*IFERROR(VLOOKUP($A13&"|Sep",Lists!$J:$L,3,FALSE),0)) | AC13: =IF(Q13="","",Q13*IFERROR(VLOOKUP($A13&"|Oct",Lists!$J:$L,2,FALSE),0)*IFERROR(VLOOKUP($A13&"|Oct",Lists!$J:$L,3,FALSE),0)) | AD13: =IF(R13="","",R13*IFERROR(VLOOKUP($A13&"|Nov",Lists!$J:$L,2,FALSE),0)*IFERROR(VLOOKUP($A13&"|Nov",Lists!$J:$L,3,FALSE),0)) | AE13: =IF(S13="","",S13*IFERROR(VLOOKUP($A13&"|Dec",Lists!$J:$L,2,FALSE),0)*IFERROR(VLOOKUP($A13&"|Dec",Lists!$J:$L,3,FALSE),0))
C14: =IFERROR(VLOOKUP($B14,Projects!$A$2:$G$50,2,FALSE),"") | D14: =IFERROR(VLOOKUP($B14,Projects!$A$2:$G$50,3,FALSE),"") | E14: =IFERROR(VLOOKUP($B14,Projects!$A$2:$G$50,4,FALSE),"") | F14: =IFERROR(VLOOKUP($B14,Projects!$A$2:$G$50,5,FALSE),"") | G14: =SUM(H14:S14) | T14: =IF($A14="","",VLOOKUP($A14,DevRateTable,3,FALSE)) | U14: =IF(I14="","",I14*IFERROR(VLOOKUP($A14&"|Feb",Lists!$J:$L,2,FALSE),0)*IFERROR(VLOOKUP($A14&"|Feb",Lists!$J:$L,3,FALSE),0)) | V14: =IF(J14="","",J14*IFERROR(VLOOKUP($A14&"|Mar",Lists!$J:$L,2,FALSE),0)*IFERROR(VLOOKUP($A14&"|Mar",Lists!$J:$L,3,FALSE),0)) | W14: =IF(K14="","",K14*IFERROR(VLOOKUP($A14&"|Apr",Lists!$J:$L,2,FALSE),0)*IFERROR(VLOOKUP($A14&"|Apr",Lists!$J:$L,3,FALSE),0)) | X14: =IF(L14="","",L14*IFERROR(VLOOKUP($A14&"|May",Lists!$J:$L,2,FALSE),0)*IFERROR(VLOOKUP($A14&"|May",Lists!$J:$L,3,FALSE),0)) | Y14: =IF(M14="","",M14*IFERROR(VLOOKUP($A14&"|Jun",Lists!$J:$L,2,FALSE),0)*IFERROR(VLOOKUP($A14&"|Jun",Lists!$J:$L,3,FALSE),0)) | Z14: =IF(N14="","",N14*IFERROR(VLOOKUP($A14&"|Jul",Lists!$J:$L,2,FALSE),0)*IFERROR(VLOOKUP($A14&"|Jul",Lists!$J:$L,3,FALSE),0)) | AA14: =IF(O14="","",O14*IFERROR(VLOOKUP($A14&"|Aug",Lists!$J:$L,2,FALSE),0)*IFERROR(VLOOKUP($A14&"|Aug",Lists!$J:$L,3,FALSE),0)) | AB14: =IF(P14="","",P14*IFERROR(VLOOKUP($A14&"|Sep",Lists!$J:$L,2,FALSE),0)*IFERROR(VLOOKUP($A14&"|Sep",Lists!$J:$L,3,FALSE),0)) | AC14: =IF(Q14="","",Q14*IFERROR(VLOOKUP($A14&"|Oct",Lists!$J:$L,2,FALSE),0)*IFERROR(VLOOKUP($A14&"|Oct",Lists!$J:$L,3,FALSE),0)) | AD14: =IF(R14="","",R14*IFERROR(VLOOKUP($A14&"|Nov",Lists!$J:$L,2,FALSE),0)*IFERROR(VLOOKUP($A14&"|Nov",Lists!$J:$L,3,FALSE),0)) | AE14: =IF(S14="","",S14*IFERROR(VLOOKUP($A14&"|Dec",Lists!$J:$L,2,FALSE),0)*IFERROR(VLOOKUP($A14&"|Dec",Lists!$J:$L,3,FALSE),0))
C15: =IFERROR(VLOOKUP($B15,Projects!$A$2:$G$50,2,FALSE),"") | D15: =IFERROR(VLOOKUP($B15,Projects!$A$2:$G$50,3,FALSE),"") | E15: =IFERROR(VLOOKUP($B15,Projects!$A$2:$G$50,4,FALSE),"") | F15: =IFERROR(VLOOKUP($B15,Projects!$A$2:$G$50,5,FALSE),"") | G15: =SUM(H15:S15) | T15: =IF($A15="","",VLOOKUP($A15,DevRateTable,3,FALSE)) | U15: =IF(I15="","",I15*IFERROR(VLOOKUP($A15&"|Feb",Lists!$J:$L,2,FALSE),0)*IFERROR(VLOOKUP($A15&"|Feb",Lists!$J:$L,3,FALSE),0)) | V15: =IF(J15="","",J15*IFERROR(VLOOKUP($A15&"|Mar",Lists!$J:$L,2,FALSE),0)*IFERROR(VLOOKUP($A15&"|Mar",Lists!$J:$L,3,FALSE),0)) | W15: =IF(K15="","",K15*IFERROR(VLOOKUP($A15&"|Apr",Lists!$J:$L,2,FALSE),0)*IFERROR(VLOOKUP($A15&"|Apr",Lists!$J:$L,3,FALSE),0)) | X15: =IF(L15="","",L15*IFERROR(VLOOKUP($A15&"|May",Lists!$J:$L,2,FALSE),0)*IFERROR(VLOOKUP($A15&"|May",Lists!$J:$L,3,FALSE),0)) | Y15: =IF(M15="","",M15*IFERROR(VLOOKUP($A15&"|Jun",Lists!$J:$L,2,FALSE),0)*IFERROR(VLOOKUP($A15&"|Jun",Lists!$J:$L,3,FALSE),0)) | Z15: =IF(N15="","",N15*IFERROR(VLOOKUP($A15&"|Jul",Lists!$J:$L,2,FALSE),0)*IFERROR(VLOOKUP($A15&"|Jul",Lists!$J:$L,3,FALSE),0)) | AA15: =IF(O15="","",O15*IFERROR(VLOOKUP($A15&"|Aug",Lists!$J:$L,2,FALSE),0)*IFERROR(VLOOKUP($A15&"|Aug",Lists!$J:$L,3,FALSE),0)) | AB15: =IF(P15="","",P15*IFERROR(VLOOKUP($A15&"|Sep",Lists!$J:$L,2,FALSE),0)*IFERROR(VLOOKUP($A15&"|Sep",Lists!$J:$L,3,FALSE),0)) | AC15: =IF(Q15="","",Q15*IFERROR(VLOOKUP($A15&"|Oct",Lists!$J:$L,2,FALSE),0)*IFERROR(VLOOKUP($A15&"|Oct",Lists!$J:$L,3,FALSE),0)) | AD15: =IF(R15="","",R15*IFERROR(VLOOKUP($A15&"|Nov",Lists!$J:$L,2,FALSE),0)*IFERROR(VLOOKUP($A15&"|Nov",Lists!$J:$L,3,FALSE),0)) | AE15: =IF(S15="","",S15*IFERROR(VLOOKUP($A15&"|Dec",Lists!$J:$L,2,FALSE),0)*IFERROR(VLOOKUP($A15&"|Dec",Lists!$J:$L,3,FALSE),0))
C16: =IFERROR(VLOOKUP($B16,Projects!$A$2:$G$50,2,FALSE),"") | D16: =IFERROR(VLOOKUP($B16,Projects!$A$2:$G$50,3,FALSE),"") | E16: =IFERROR(VLOOKUP($B16,Projects!$A$2:$G$50,4,FALSE),"") | F16: =IFERROR(VLOOKUP($B16,Projects!$A$2:$G$50,5,FALSE),"") | G16: =SUM(H16:S16) | T16: =IF($A16="","",VLOOKUP($A16,DevRateTable,3,FALSE)) | U16: =IF(I16="","",I16*IFERROR(VLOOKUP($A16&"|Feb",Lists!$J:$L,2,FALSE),0)*IFERROR(VLOOKUP($A16&"|Feb",Lists!$J:$L,3,FALSE),0)) | V16: =IF(J16="","",J16*IFERROR(VLOOKUP($A16&"|Mar",Lists!$J:$L,2,FALSE),0)*IFERROR(VLOOKUP($A16&"|Mar",Lists!$J:$L,3,FALSE),0)) | W16: =IF(K16="","",K16*IFERROR(VLOOKUP($A16&"|Apr",Lists!$J:$L,2,FALSE),0)*IFERROR(VLOOKUP($A16&"|Apr",Lists!$J:$L,3,FALSE),0)) | X16: =IF(L16="","",L16*IFERROR(VLOOKUP($A16&"|May",Lists!$J:$L,2,FALSE),0)*IFERROR(VLOOKUP($A16&"|May",Lists!$J:$L,3,FALSE),0)) | Y16: =IF(M16="","",M16*IFERROR(VLOOKUP($A16&"|Jun",Lists!$J:$L,2,FALSE),0)*IFERROR(VLOOKUP($A16&"|Jun",Lists!$J:$L,3,FALSE),0)) | Z16: =IF(N16="","",N16*IFERROR(VLOOKUP($A16&"|Jul",Lists!$J:$L,2,FALSE),0)*IFERROR(VLOOKUP($A16&"|Jul",Lists!$J:$L,3,FALSE),0)) | AA16: =IF(O16="","",O16*IFERROR(VLOOKUP($A16&"|Aug",Lists!$J:$L,2,FALSE),0)*IFERROR(VLOOKUP($A16&"|Aug",Lists!$J:$L,3,FALSE),0)) | AB16: =IF(P16="","",P16*IFERROR(VLOOKUP($A16&"|Sep",Lists!$J:$L,2,FALSE),0)*IFERROR(VLOOKUP($A16&"|Sep",Lists!$J:$L,3,FALSE),0)) | AC16: =IF(Q16="","",Q16*IFERROR(VLOOKUP($A16&"|Oct",Lists!$J:$L,2,FALSE),0)*IFERROR(VLOOKUP($A16&"|Oct",Lists!$J:$L,3,FALSE),0)) | AD16: =IF(R16="","",R16*IFERROR(VLOOKUP($A16&"|Nov",Lists!$J:$L,2,FALSE),0)*IFERROR(VLOOKUP($A16&"|Nov",Lists!$J:$L,3,FALSE),0)) | AE16: =IF(S16="","",S16*IFERROR(VLOOKUP($A16&"|Dec",Lists!$J:$L,2,FALSE),0)*IFERROR(VLOOKUP($A16&"|Dec",Lists!$J:$L,3,FALSE),0))
C17: =IFERROR(VLOOKUP($B17,Projects!$A$2:$G$50,2,FALSE),"") | D17: =IFERROR(VLOOKUP($B17,Projects!$A$2:$G$50,3,FALSE),"") | E17: =IFERROR(VLOOKUP($B17,Projects!$A$2:$G$50,4,FALSE),"") | F17: =IFERROR(VLOOKUP($B17,Projects!$A$2:$G$50,5,FALSE),"") | G17: =SUM(H17:S17) | T17: =IF($A17="","",VLOOKUP($A17,DevRateTable,3,FALSE)) | U17: =IF(I17="","",I17*IFERROR(VLOOKUP($A17&"|Feb",Lists!$J:$L,2,FALSE),0)*IFERROR(VLOOKUP($A17&"|Feb",Lists!$J:$L,3,FALSE),0)) | V17: =IF(J17="","",J17*IFERROR(VLOOKUP($A17&"|Mar",Lists!$J:$L,2,FALSE),0)*IFERROR(VLOOKUP($A17&"|Mar",Lists!$J:$L,3,FALSE),0)) | W17: =IF(K17="","",K17*IFERROR(VLOOKUP($A17&"|Apr",Lists!$J:$L,2,FALSE),0)*IFERROR(VLOOKUP($A17&"|Apr",Lists!$J:$L,3,FALSE),0)) | X17: =IF(L17="","",L17*IFERROR(VLOOKUP($A17&"|May",Lists!$J:$L,2,FALSE),0)*IFERROR(VLOOKUP($A17&"|May",Lists!$J:$L,3,FALSE),0)) | Y17: =IF(M17="","",M17*IFERROR(VLOOKUP($A17&"|Jun",Lists!$J:$L,2,FALSE),0)*IFERROR(VLOOKUP($A17&"|Jun",Lists!$J:$L,3,FALSE),0)) | Z17: =IF(N17="","",N17*IFERROR(VLOOKUP($A17&"|Jul",Lists!$J:$L,2,FALSE),0)*IFERROR(VLOOKUP($A17&"|Jul",Lists!$J:$L,3,FALSE),0)) | AA17: =IF(O17="","",O17*IFERROR(VLOOKUP($A17&"|Aug",Lists!$J:$L,2,FALSE),0)*IFERROR(VLOOKUP($A17&"|Aug",Lists!$J:$L,3,FALSE),0)) | AB17: =IF(P17="","",P17*IFERROR(VLOOKUP($A17&"|Sep",Lists!$J:$L,2,FALSE),0)*IFERROR(VLOOKUP($A17&"|Sep",Lists!$J:$L,3,FALSE),0)) | AC17: =IF(Q17="","",Q17*IFERROR(VLOOKUP($A17&"|Oct",Lists!$J:$L,2,FALSE),0)*IFERROR(VLOOKUP($A17&"|Oct",Lists!$J:$L,3,FALSE),0)) | AD17: =IF(R17="","",R17*IFERROR(VLOOKUP($A17&"|Nov",Lists!$J:$L,2,FALSE),0)*IFERROR(VLOOKUP($A17&"|Nov",Lists!$J:$L,3,FALSE),0)) | AE17: =IF(S17="","",S17*IFERROR(VLOOKUP($A17&"|Dec",Lists!$J:$L,2,FALSE),0)*IFERROR(VLOOKUP($A17&"|Dec",Lists!$J:$L,3,FALSE),0))
C18: =IFERROR(VLOOKUP($B18,Projects!$A$2:$G$50,2,FALSE),"") | D18: =IFERROR(VLOOKUP($B18,Projects!$A$2:$G$50,3,FALSE),"") | E18: =IFERROR(VLOOKUP($B18,Projects!$A$2:$G$50,4,FALSE),"") | F18: =IFERROR(VLOOKUP($B18,Projects!$A$2:$G$50,5,FALSE),"") | G18: =SUM(H18:S18) | T18: =IF($A18="","",VLOOKUP($A18,DevRateTable,3,FALSE)) | U18: =IF(I18="","",I18*IFERROR(VLOOKUP($A18&"|Feb",Lists!$J:$L,2,FALSE),0)*IFERROR(VLOOKUP($A18&"|Feb",Lists!$J:$L,3,FALSE),0)) | V18: =IF(J18="","",J18*IFERROR(VLOOKUP($A18&"|Mar",Lists!$J:$L,2,FALSE),0)*IFERROR(VLOOKUP($A18&"|Mar",Lists!$J:$L,3,FALSE),0)) | W18: =IF(K18="","",K18*IFERROR(VLOOKUP($A18&"|Apr",Lists!$J:$L,2,FALSE),0)*IFERROR(VLOOKUP($A18&"|Apr",Lists!$J:$L,3,FALSE),0)) | X18: =IF(L18="","",L18*IFERROR(VLOOKUP($A18&"|May",Lists!$J:$L,2,FALSE),0)*IFERROR(VLOOKUP($A18&"|May",Lists!$J:$L,3,FALSE),0)) | Y18: =IF(M18="","",M18*IFERROR(VLOOKUP($A18&"|Jun",Lists!$J:$L,2,FALSE),0)*IFERROR(VLOOKUP($A18&"|Jun",Lists!$J:$L,3,FALSE),0)) | Z18: =IF(N18="","",N18*IFERROR(VLOOKUP($A18&"|Jul",Lists!$J:$L,2,FALSE),0)*IFERROR(VLOOKUP($A18&"|Jul",Lists!$J:$L,3,FALSE),0)) | AA18: =IF(O18="","",O18*IFERROR(VLOOKUP($A18&"|Aug",Lists!$J:$L,2,FALSE),0)*IFERROR(VLOOKUP($A18&"|Aug",Lists!$J:$L,3,FALSE),0)) | AB18: =IF(P18="","",P18*IFERROR(VLOOKUP($A18&"|Sep",Lists!$J:$L,2,FALSE),0)*IFERROR(VLOOKUP($A18&"|Sep",Lists!$J:$L,3,FALSE),0)) | AC18: =IF(Q18="","",Q18*IFERROR(VLOOKUP($A18&"|Oct",Lists!$J:$L,2,FALSE),0)*IFERROR(VLOOKUP($A18&"|Oct",Lists!$J:$L,3,FALSE),0)) | AD18: =IF(R18="","",R18*IFERROR(VLOOKUP($A18&"|Nov",Lists!$J:$L,2,FALSE),0)*IFERROR(VLOOKUP($A18&"|Nov",Lists!$J:$L,3,FALSE),0)) | AE18: =IF(S18="","",S18*IFERROR(VLOOKUP($A18&"|Dec",Lists!$J:$L,2,FALSE),0)*IFERROR(VLOOKUP($A18&"|Dec",Lists!$J:$L,3,FALSE),0))
C19: =IFERROR(VLOOKUP($B19,Projects!$A$2:$G$50,2,FALSE),"") | D19: =IFERROR(VLOOKUP($B19,Projects!$A$2:$G$50,3,FALSE),"") | E19: =IFERROR(VLOOKUP($B19,Projects!$A$2:$G$50,4,FALSE),"") | F19: =IFERROR(VLOOKUP($B19,Projects!$A$2:$G$50,5,FALSE),"") | G19: =SUM(H19:S19) | T19: =IF($A19="","",VLOOKUP($A19,DevRateTable,3,FALSE)) | U19: =IF(I19="","",I19*IFERROR(VLOOKUP($A19&"|Feb",Lists!$J:$L,2,FALSE),0)*IFERROR(VLOOKUP($A19&"|Feb",Lists!$J:$L,3,FALSE),0)) | V19: =IF(J19="","",J19*IFERROR(VLOOKUP($A19&"|Mar",Lists!$J:$L,2,FALSE),0)*IFERROR(VLOOKUP($A19&"|Mar",Lists!$J:$L,3,FALSE),0)) | W19: =IF(K19="","",K19*IFERROR(VLOOKUP($A19&"|Apr",Lists!$J:$L,2,FALSE),0)*IFERROR(VLOOKUP($A19&"|Apr",Lists!$J:$L,3,FALSE),0)) | X19: =IF(L19="","",L19*IFERROR(VLOOKUP($A19&"|May",Lists!$J:$L,2,FALSE),0)*IFERROR(VLOOKUP($A19&"|May",Lists!$J:$L,3,FALSE),0)) | Y19: =IF(M19="","",M19*IFERROR(VLOOKUP($A19&"|Jun",Lists!$J:$L,2,FALSE),0)*IFERROR(VLOOKUP($A19&"|Jun",Lists!$J:$L,3,FALSE),0)) | Z19: =IF(N19="","",N19*IFERROR(VLOOKUP($A19&"|Jul",Lists!$J:$L,2,FALSE),0)*IFERROR(VLOOKUP($A19&"|Jul",Lists!$J:$L,3,FALSE),0)) | AA19: =IF(O19="","",O19*IFERROR(VLOOKUP($A19&"|Aug",Lists!$J:$L,2,FALSE),0)*IFERROR(VLOOKUP($A19&"|Aug",Lists!$J:$L,3,FALSE),0)) | AB19: =IF(P19="","",P19*IFERROR(VLOOKUP($A19&"|Sep",Lists!$J:$L,2,FALSE),0)*IFERROR(VLOOKUP($A19&"|Sep",Lists!$J:$L,3,FALSE),0)) | AC19: =IF(Q19="","",Q19*IFERROR(VLOOKUP($A19&"|Oct",Lists!$J:$L,2,FALSE),0)*IFERROR(VLOOKUP($A19&"|Oct",Lists!$J:$L,3,FALSE),0)) | AD19: =IF(R19="","",R19*IFERROR(VLOOKUP($A19&"|Nov",Lists!$J:$L,2,FALSE),0)*IFERROR(VLOOKUP($A19&"|Nov",Lists!$J:$L,3,FALSE),0)) | AE19: =IF(S19="","",S19*IFERROR(VLOOKUP($A19&"|Dec",Lists!$J:$L,2,FALSE),0)*IFERROR(VLOOKUP($A19&"|Dec",Lists!$J:$L,3,FALSE),0))
C20: =IFERROR(VLOOKUP($B20,Projects!$A$2:$G$50,2,FALSE),"") | D20: =IFERROR(VLOOKUP($B20,Projects!$A$2:$G$50,3,FALSE),"") | E20: =IFERROR(VLOOKUP($B20,Projects!$A$2:$G$50,4,FALSE),"") | F20: =IFERROR(VLOOKUP($B20,Projects!$A$2:$G$50,5,FALSE),"") | G20: =SUM(H20:S20) | T20: =IF($A20="","",VLOOKUP($A20,DevRateTable,3,FALSE)) | U20: =IF(I20="","",I20*IFERROR(VLOOKUP($A20&"|Feb",Lists!$J:$L,2,FALSE),0)*IFERROR(VLOOKUP($A20&"|Feb",Lists!$J:$L,3,FALSE),0)) | V20: =IF(J20="","",J20*IFERROR(VLOOKUP($A20&"|Mar",Lists!$J:$L,2,FALSE),0)*IFERROR(VLOOKUP($A20&"|Mar",Lists!$J:$L,3,FALSE),0)) | W20: =IF(K20="","",K20*IFERROR(VLOOKUP($A20&"|Apr",Lists!$J:$L,2,FALSE),0)*IFERROR(VLOOKUP($A20&"|Apr",Lists!$J:$L,3,FALSE),0)) | X20: =IF(L20="","",L20*IFERROR(VLOOKUP($A20&"|May",Lists!$J:$L,2,FALSE),0)*IFERROR(VLOOKUP($A20&"|May",Lists!$J:$L,3,FALSE),0)) | Y20: =IF(M20="","",M20*IFERROR(VLOOKUP($A20&"|Jun",Lists!$J:$L,2,FALSE),0)*IFERROR(VLOOKUP($A20&"|Jun",Lists!$J:$L,3,FALSE),0)) | Z20: =IF(N20="","",N20*IFERROR(VLOOKUP($A20&"|Jul",Lists!$J:$L,2,FALSE),0)*IFERROR(VLOOKUP($A20&"|Jul",Lists!$J:$L,3,FALSE),0)) | AA20: =IF(O20="","",O20*IFERROR(VLOOKUP($A20&"|Aug",Lists!$J:$L,2,FALSE),0)*IFERROR(VLOOKUP($A20&"|Aug",Lists!$J:$L,3,FALSE),0)) | AB20: =IF(P20="","",P20*IFERROR(VLOOKUP($A20&"|Sep",Lists!$J:$L,2,FALSE),0)*IFERROR(VLOOKUP($A20&"|Sep",Lists!$J:$L,3,FALSE),0)) | AC20: =IF(Q20="","",Q20*IFERROR(VLOOKUP($A20&"|Oct",Lists!$J:$L,2,FALSE),0)*IFERROR(VLOOKUP($A20&"|Oct",Lists!$J:$L,3,FALSE),0)) | AD20: =IF(R20="","",R20*IFERROR(VLOOKUP($A20&"|Nov",Lists!$J:$L,2,FALSE),0)*IFERROR(VLOOKUP($A20&"|Nov",Lists!$J:$L,3,FALSE),0)) | AE20: =IF(S20="","",S20*IFERROR(VLOOKUP($A20&"|Dec",Lists!$J:$L,2,FALSE),0)*IFERROR(VLOOKUP($A20&"|Dec",Lists!$J:$L,3,FALSE),0))
C21: =IFERROR(VLOOKUP($B21,Projects!$A$2:$G$50,2,FALSE),"") | D21: =IFERROR(VLOOKUP($B21,Projects!$A$2:$G$50,3,FALSE),"") | E21: =IFERROR(VLOOKUP($B21,Projects!$A$2:$G$50,4,FALSE),"") | F21: =IFERROR(VLOOKUP($B21,Projects!$A$2:$G$50,5,FALSE),"") | G21: =SUM(H21:S21) | T21: =IF($A21="","",VLOOKUP($A21,DevRateTable,3,FALSE)) | U21: =IF(I21="","",I21*IFERROR(VLOOKUP($A21&"|Feb",Lists!$J:$L,2,FALSE),0)*IFERROR(VLOOKUP($A21&"|Feb",Lists!$J:$L,3,FALSE),0)) | V21: =IF(J21="","",J21*IFERROR(VLOOKUP($A21&"|Mar",Lists!$J:$L,2,FALSE),0)*IFERROR(VLOOKUP($A21&"|Mar",Lists!$J:$L,3,FALSE),0)) | W21: =IF(K21="","",K21*IFERROR(VLOOKUP($A21&"|Apr",Lists!$J:$L,2,FALSE),0)*IFERROR(VLOOKUP($A21&"|Apr",Lists!$J:$L,3,FALSE),0)) | X21: =IF(L21="","",L21*IFERROR(VLOOKUP($A21&"|May",Lists!$J:$L,2,FALSE),0)*IFERROR(VLOOKUP($A21&"|May",Lists!$J:$L,3,FALSE),0)) | Y21: =IF(M21="","",M21*IFERROR(VLOOKUP($A21&"|Jun",Lists!$J:$L,2,FALSE),0)*IFERROR(VLOOKUP($A21&"|Jun",Lists!$J:$L,3,FALSE),0)) | Z21: =IF(N21="","",N21*IFERROR(VLOOKUP($A21&"|Jul",Lists!$J:$L,2,FALSE),0)*IFERROR(VLOOKUP($A21&"|Jul",Lists!$J:$L,3,FALSE),0)) | AA21: =IF(O21="","",O21*IFERROR(VLOOKUP($A21&"|Aug",Lists!$J:$L,2,FALSE),0)*IFERROR(VLOOKUP($A21&"|Aug",Lists!$J:$L,3,FALSE),0)) | AB21: =IF(P21="","",P21*IFERROR(VLOOKUP($A21&"|Sep",Lists!$J:$L,2,FALSE),0)*IFERROR(VLOOKUP($A21&"|Sep",Lists!$J:$L,3,FALSE),0)) | AC21: =IF(Q21="","",Q21*IFERROR(VLOOKUP($A21&"|Oct",Lists!$J:$L,2,FALSE),0)*IFERROR(VLOOKUP($A21&"|Oct",Lists!$J:$L,3,FALSE),0)) | AD21: =IF(R21="","",R21*IFERROR(VLOOKUP($A21&"|Nov",Lists!$J:$L,2,FALSE),0)*IFERROR(VLOOKUP($A21&"|Nov",Lists!$J:$L,3,FALSE),0)) | AE21: =IF(S21="","",S21*IFERROR(VLOOKUP($A21&"|Dec",Lists!$J:$L,2,FALSE),0)*IFERROR(VLOOKUP($A21&"|Dec",Lists!$J:$L,3,FALSE),0))
C22: =IFERROR(VLOOKUP($B22,Projects!$A$2:$G$50,2,FALSE),"") | D22: =IFERROR(VLOOKUP($B22,Projects!$A$2:$G$50,3,FALSE),"") | E22: =IFERROR(VLOOKUP($B22,Projects!$A$2:$G$50,4,FALSE),"") | F22: =IFERROR(VLOOKUP($B22,Projects!$A$2:$G$50,5,FALSE),"") | G22: =SUM(H22:S22) | T22: =IF($A22="","",VLOOKUP($A22,DevRateTable,3,FALSE)) | U22: =IF(I22="","",I22*IFERROR(VLOOKUP($A22&"|Feb",Lists!$J:$L,2,FALSE),0)*IFERROR(VLOOKUP($A22&"|Feb",Lists!$J:$L,3,FALSE),0)) | V22: =IF(J22="","",J22*IFERROR(VLOOKUP($A22&"|Mar",Lists!$J:$L,2,FALSE),0)*IFERROR(VLOOKUP($A22&"|Mar",Lists!$J:$L,3,FALSE),0)) | W22: =IF(K22="","",K22*IFERROR(VLOOKUP($A22&"|Apr",Lists!$J:$L,2,FALSE),0)*IFERROR(VLOOKUP($A22&"|Apr",Lists!$J:$L,3,FALSE),0)) | X22: =IF(L22="","",L22*IFERROR(VLOOKUP($A22&"|May",Lists!$J:$L,2,FALSE),0)*IFERROR(VLOOKUP($A22&"|May",Lists!$J:$L,3,FALSE),0)) | Y22: =IF(M22="","",M22*IFERROR(VLOOKUP($A22&"|Jun",Lists!$J:$L,2,FALSE),0)*IFERROR(VLOOKUP($A22&"|Jun",Lists!$J:$L,3,FALSE),0)) | Z22: =IF(N22="","",N22*IFERROR(VLOOKUP($A22&"|Jul",Lists!$J:$L,2,FALSE),0)*IFERROR(VLOOKUP($A22&"|Jul",Lists!$J:$L,3,FALSE),0)) | AA22: =IF(O22="","",O22*IFERROR(VLOOKUP($A22&"|Aug",Lists!$J:$L,2,FALSE),0)*IFERROR(VLOOKUP($A22&"|Aug",Lists!$J:$L,3,FALSE),0)) | AB22: =IF(P22="","",P22*IFERROR(VLOOKUP($A22&"|Sep",Lists!$J:$L,2,FALSE),0)*IFERROR(VLOOKUP($A22&"|Sep",Lists!$J:$L,3,FALSE),0)) | AC22: =IF(Q22="","",Q22*IFERROR(VLOOKUP($A22&"|Oct",Lists!$J:$L,2,FALSE),0)*IFERROR(VLOOKUP($A22&"|Oct",Lists!$J:$L,3,FALSE),0)) | AD22: =IF(R22="","",R22*IFERROR(VLOOKUP($A22&"|Nov",Lists!$J:$L,2,FALSE),0)*IFERROR(VLOOKUP($A22&"|Nov",Lists!$J:$L,3,FALSE),0)) | AE22: =IF(S22="","",S22*IFERROR(VLOOKUP($A22&"|Dec",Lists!$J:$L,2,FALSE),0)*IFERROR(VLOOKUP($A22&"|Dec",Lists!$J:$L,3,FALSE),0))
... C52: =IFERROR(VLOOKUP($B52,Projects!$A$2:$G$50,2,FALSE),"") | D52: =IFERROR(VLOOKUP($B52,Projects!$A$2:$G$50,3,FALSE),"") | E52: =IFERROR(VLOOKUP($B52,Projects!$A$2:$G$50,4,FALSE),"") | F52: =IFERROR(VLOOKUP($B52,Projects!$A$2:$G$50,5,FALSE),"") | G52: =SUM(H52:S52) | T52: =IF($A52="","",VLOOKUP($A52,DevRateTable,3,FALSE)) | U52: =IF(I52="","",I52*IFERROR(VLOOKUP($A52&"|Feb",Lists!$J:$L,2,FALSE),0)*IFERROR(VLOOKUP($A52&"|Feb",Lists!$J:$L,3,FALSE),0)) | V52: =IF(J52="","",J52*IFERROR(VLOOKUP($A52&"|Mar",Lists!$J:$L,2,FALSE),0)*IFERROR(VLOOKUP($A52&"|Mar",Lists!$J:$L,3,FALSE),0)) | W52: =IF(K52="","",K52*IFERROR(VLOOKUP($A52&"|Apr",Lists!$J:$L,2,FALSE),0)*IFERROR(VLOOKUP($A52&"|Apr",Lists!$J:$L,3,FALSE),0)) | X52: =IF(L52="","",L52*IFERROR(VLOOKUP($A52&"|May",Lists!$J:$L,2,FALSE),0)*IFERROR(VLOOKUP($A52&"|May",Lists!$J:$L,3,FALSE),0)) | Y52: =IF(M52="","",M52*IFERROR(VLOOKUP($A52&"|Jun",Lists!$J:$L,2,FALSE),0)*IFERROR(VLOOKUP($A52&"|Jun",Lists!$J:$L,3,FALSE),0)) | Z52: =IF(N52="","",N52*IFERROR(VLOOKUP($A52&"|Jul",Lists!$J:$L,2,FALSE),0)*IFERROR(VLOOKUP($A52&"|Jul",Lists!$J:$L,3,FALSE),0)) | AA52: =IF(O52="","",O52*IFERROR(VLOOKUP($A52&"|Aug",Lists!$J:$L,2,FALSE),0)*IFERROR(VLOOKUP($A52&"|Aug",Lists!$J:$L,3,FALSE),0)) | AB52: =IF(P52="","",P52*IFERROR(VLOOKUP($A52&"|Sep",Lists!$J:$L,2,FALSE),0)*IFERROR(VLOOKUP($A52&"|Sep",Lists!$J:$L,3,FALSE),0)) | AC52: =IF(Q52="","",Q52*IFERROR(VLOOKUP($A52&"|Oct",Lists!$J:$L,2,FALSE),0)*IFERROR(VLOOKUP($A52&"|Oct",Lists!$J:$L,3,FALSE),0)) | AD52: =IF(R52="","",R52*IFERROR(VLOOKUP($A52&"|Nov",Lists!$J:$L,2,FALSE),0)*IFERROR(VLOOKUP($A52&"|Nov",Lists!$J:$L,3,FALSE),0)) | AE52: =IF(S52="","",S52*IFERROR(VLOOKUP($A52&"|Dec",Lists!$J:$L,2,FALSE),0)*IFERROR(VLOOKUP($A52&"|Dec",Lists!$J:$L,3,FALSE),0))
T53: =IF($A53="","",VLOOKUP($A53,DevRateTable,3,FALSE)) | U53: =IF(I53="","",I53*IFERROR(VLOOKUP($A53&"|Feb",Lists!$J:$L,2,FALSE),0)*IFERROR(VLOOKUP($A53&"|Feb",Lists!$J:$L,3,FALSE),0)) | V53: =IF(J53="","",J53*IFERROR(VLOOKUP($A53&"|Mar",Lists!$J:$L,2,FALSE),0)*IFERROR(VLOOKUP($A53&"|Mar",Lists!$J:$L,3,FALSE),0)) | W53: =IF(K53="","",K53*IFERROR(VLOOKUP($A53&"|Apr",Lists!$J:$L,2,FALSE),0)*IFERROR(VLOOKUP($A53&"|Apr",Lists!$J:$L,3,FALSE),0)) | X53: =IF(L53="","",L53*IFERROR(VLOOKUP($A53&"|May",Lists!$J:$L,2,FALSE),0)*IFERROR(VLOOKUP($A53&"|May",Lists!$J:$L,3,FALSE),0)) | Y53: =IF(M53="","",M53*IFERROR(VLOOKUP($A53&"|Jun",Lists!$J:$L,2,FALSE),0)*IFERROR(VLOOKUP($A53&"|Jun",Lists!$J:$L,3,FALSE),0)) | Z53: =IF(N53="","",N53*IFERROR(VLOOKUP($A53&"|Jul",Lists!$J:$L,2,FALSE),0)*IFERROR(VLOOKUP($A53&"|Jul",Lists!$J:$L,3,FALSE),0)) | AA53: =IF(O53="","",O53*IFERROR(VLOOKUP($A53&"|Aug",Lists!$J:$L,2,FALSE),0)*IFERROR(VLOOKUP($A53&"|Aug",Lists!$J:$L,3,FALSE),0)) | AB53: =IF(P53="","",P53*IFERROR(VLOOKUP($A53&"|Sep",Lists!$J:$L,2,FALSE),0)*IFERROR(VLOOKUP($A53&"|Sep",Lists!$J:$L,3,FALSE),0)) | AC53: =IF(Q53="","",Q53*IFERROR(VLOOKUP($A53&"|Oct",Lists!$J:$L,2,FALSE),0)*IFERROR(VLOOKUP($A53&"|Oct",Lists!$J:$L,3,FALSE),0)) | AD53: =IF(R53="","",R53*IFERROR(VLOOKUP($A53&"|Nov",Lists!$J:$L,2,FALSE),0)*IFERROR(VLOOKUP($A53&"|Nov",Lists!$J:$L,3,FALSE),0)) | AE53: =IF(S53="","",S53*IFERROR(VLOOKUP($A53&"|Dec",Lists!$J:$L,2,FALSE),0)*IFERROR(VLOOKUP($A53&"|Dec",Lists!$J:$L,3,FALSE),0))
T54: =IF($A54="","",VLOOKUP($A54,DevRateTable,3,FALSE)) | U54: =IF(I54="","",I54*IFERROR(VLOOKUP($A54&"|Feb",Lists!$J:$L,2,FALSE),0)*IFERROR(VLOOKUP($A54&"|Feb",Lists!$J:$L,3,FALSE),0)) | V54: =IF(J54="","",J54*IFERROR(VLOOKUP($A54&"|Mar",Lists!$J:$L,2,FALSE),0)*IFERROR(VLOOKUP($A54&"|Mar",Lists!$J:$L,3,FALSE),0)) | W54: =IF(K54="","",K54*IFERROR(VLOOKUP($A54&"|Apr",Lists!$J:$L,2,FALSE),0)*IFERROR(VLOOKUP($A54&"|Apr",Lists!$J:$L,3,FALSE),0)) | X54: =IF(L54="","",L54*IFERROR(VLOOKUP($A54&"|May",Lists!$J:$L,2,FALSE),0)*IFERROR(VLOOKUP($A54&"|May",Lists!$J:$L,3,FALSE),0)) | Y54: =IF(M54="","",M54*IFERROR(VLOOKUP($A54&"|Jun",Lists!$J:$L,2,FALSE),0)*IFERROR(VLOOKUP($A54&"|Jun",Lists!$J:$L,3,FALSE),0)) | Z54: =IF(N54="","",N54*IFERROR(VLOOKUP($A54&"|Jul",Lists!$J:$L,2,FALSE),0)*IFERROR(VLOOKUP($A54&"|Jul",Lists!$J:$L,3,FALSE),0)) | AA54: =IF(O54="","",O54*IFERROR(VLOOKUP($A54&"|Aug",Lists!$J:$L,2,FALSE),0)*IFERROR(VLOOKUP($A54&"|Aug",Lists!$J:$L,3,FALSE),0)) | AB54: =IF(P54="","",P54*IFERROR(VLOOKUP($A54&"|Sep",Lists!$J:$L,2,FALSE),0)*IFERROR(VLOOKUP($A54&"|Sep",Lists!$J:$L,3,FALSE),0)) | AC54: =IF(Q54="","",Q54*IFERROR(VLOOKUP($A54&"|Oct",Lists!$J:$L,2,FALSE),0)*IFERROR(VLOOKUP($A54&"|Oct",Lists!$J:$L,3,FALSE),0)) | AD54: =IF(R54="","",R54*IFERROR(VLOOKUP($A54&"|Nov",Lists!$J:$L,2,FALSE),0)*IFERROR(VLOOKUP($A54&"|Nov",Lists!$J:$L,3,FALSE),0)) | AE54: =IF(S54="","",S54*IFERROR(VLOOKUP($A54&"|Dec",Lists!$J:$L,2,FALSE),0)*IFERROR(VLOOKUP($A54&"|Dec",Lists!$J:$L,3,FALSE),0))
T55: =IF($A55="","",VLOOKUP($A55,DevRateTable,3,FALSE)) | U55: =IF(I55="","",I55*IFERROR(VLOOKUP($A55&"|Feb",Lists!$J:$L,2,FALSE),0)*IFERROR(VLOOKUP($A55&"|Feb",Lists!$J:$L,3,FALSE),0)) | V55: =IF(J55="","",J55*IFERROR(VLOOKUP($A55&"|Mar",Lists!$J:$L,2,FALSE),0)*IFERROR(VLOOKUP($A55&"|Mar",Lists!$J:$L,3,FALSE),0)) | W55: =IF(K55="","",K55*IFERROR(VLOOKUP($A55&"|Apr",Lists!$J:$L,2,FALSE),0)*IFERROR(VLOOKUP($A55&"|Apr",Lists!$J:$L,3,FALSE),0)) | X55: =IF(L55="","",L55*IFERROR(VLOOKUP($A55&"|May",Lists!$J:$L,2,FALSE),0)*IFERROR(VLOOKUP($A55&"|May",Lists!$J:$L,3,FALSE),0)) | Y55: =IF(M55="","",M55*IFERROR(VLOOKUP($A55&"|Jun",Lists!$J:$L,2,FALSE),0)*IFERROR(VLOOKUP($A55&"|Jun",Lists!$J:$L,3,FALSE),0)) | Z55: =IF(N55="","",N55*IFERROR(VLOOKUP($A55&"|Jul",Lists!$J:$L,2,FALSE),0)*IFERROR(VLOOKUP($A55&"|Jul",Lists!$J:$L,3,FALSE),0)) | AA55: =IF(O55="","",O55*IFERROR(VLOOKUP($A55&"|Aug",Lists!$J:$L,2,FALSE),0)*IFERROR(VLOOKUP($A55&"|Aug",Lists!$J:$L,3,FALSE),0)) | AB55: =IF(P55="","",P55*IFERROR(VLOOKUP($A55&"|Sep",Lists!$J:$L,2,FALSE),0)*IFERROR(VLOOKUP($A55&"|Sep",Lists!$J:$L,3,FALSE),0)) | AC55: =IF(Q55="","",Q55*IFERROR(VLOOKUP($A55&"|Oct",Lists!$J:$L,2,FALSE),0)*IFERROR(VLOOKUP($A55&"|Oct",Lists!$J:$L,3,FALSE),0)) | AD55: =IF(R55="","",R55*IFERROR(VLOOKUP($A55&"|Nov",Lists!$J:$L,2,FALSE),0)*IFERROR(VLOOKUP($A55&"|Nov",Lists!$J:$L,3,FALSE),0)) | AE55: =IF(S55="","",S55*IFERROR(VLOOKUP($A55&"|Dec",Lists!$J:$L,2,FALSE),0)*IFERROR(VLOOKUP($A55&"|Dec",Lists!$J:$L,3,FALSE),0))
T56: =IF($A56="","",VLOOKUP($A56,DevRateTable,3,FALSE)) | U56: =IF(I56="","",I56*IFERROR(VLOOKUP($A56&"|Feb",Lists!$J:$L,2,FALSE),0)*IFERROR(VLOOKUP($A56&"|Feb",Lists!$J:$L,3,FALSE),0)) | V56: =IF(J56="","",J56*IFERROR(VLOOKUP($A56&"|Mar",Lists!$J:$L,2,FALSE),0)*IFERROR(VLOOKUP($A56&"|Mar",Lists!$J:$L,3,FALSE),0)) | W56: =IF(K56="","",K56*IFERROR(VLOOKUP($A56&"|Apr",Lists!$J:$L,2,FALSE),0)*IFERROR(VLOOKUP($A56&"|Apr",Lists!$J:$L,3,FALSE),0)) | X56: =IF(L56="","",L56*IFERROR(VLOOKUP($A56&"|May",Lists!$J:$L,2,FALSE),0)*IFERROR(VLOOKUP($A56&"|May",Lists!$J:$L,3,FALSE),0)) | Y56: =IF(M56="","",M56*IFERROR(VLOOKUP($A56&"|Jun",Lists!$J:$L,2,FALSE),0)*IFERROR(VLOOKUP($A56&"|Jun",Lists!$J:$L,3,FALSE),0)) | Z56: =IF(N56="","",N56*IFERROR(VLOOKUP($A56&"|Jul",Lists!$J:$L,2,FALSE),0)*IFERROR(VLOOKUP($A56&"|Jul",Lists!$J:$L,3,FALSE),0)) | AA56: =IF(O56="","",O56*IFERROR(VLOOKUP($A56&"|Aug",Lists!$J:$L,2,FALSE),0)*IFERROR(VLOOKUP($A56&"|Aug",Lists!$J:$L,3,FALSE),0)) | AB56: =IF(P56="","",P56*IFERROR(VLOOKUP($A56&"|Sep",Lists!$J:$L,2,FALSE),0)*IFERROR(VLOOKUP($A56&"|Sep",Lists!$J:$L,3,FALSE),0)) | AC56: =IF(Q56="","",Q56*IFERROR(VLOOKUP($A56&"|Oct",Lists!$J:$L,2,FALSE),0)*IFERROR(VLOOKUP($A56&"|Oct",Lists!$J:$L,3,FALSE),0)) | AD56: =IF(R56="","",R56*IFERROR(VLOOKUP($A56&"|Nov",Lists!$J:$L,2,FALSE),0)*IFERROR(VLOOKUP($A56&"|Nov",Lists!$J:$L,3,FALSE),0)) | AE56: =IF(S56="","",S56*IFERROR(VLOOKUP($A56&"|Dec",Lists!$J:$L,2,FALSE),0)*IFERROR(VLOOKUP($A56&"|Dec",Lists!$J:$L,3,FALSE),0))
T57: =IF($A57="","",VLOOKUP($A57,DevRateTable,3,FALSE)) | U57: =IF(I57="","",I57*IFERROR(VLOOKUP($A57&"|Feb",Lists!$J:$L,2,FALSE),0)*IFERROR(VLOOKUP($A57&"|Feb",Lists!$J:$L,3,FALSE),0)) | V57: =IF(J57="","",J57*IFERROR(VLOOKUP($A57&"|Mar",Lists!$J:$L,2,FALSE),0)*IFERROR(VLOOKUP($A57&"|Mar",Lists!$J:$L,3,FALSE),0)) | W57: =IF(K57="","",K57*IFERROR(VLOOKUP($A57&"|Apr",Lists!$J:$L,2,FALSE),0)*IFERROR(VLOOKUP($A57&"|Apr",Lists!$J:$L,3,FALSE),0)) | X57: =IF(L57="","",L57*IFERROR(VLOOKUP($A57&"|May",Lists!$J:$L,2,FALSE),0)*IFERROR(VLOOKUP($A57&"|May",Lists!$J:$L,3,FALSE),0)) | Y57: =IF(M57="","",M57*IFERROR(VLOOKUP($A57&"|Jun",Lists!$J:$L,2,FALSE),0)*IFERROR(VLOOKUP($A57&"|Jun",Lists!$J:$L,3,FALSE),0)) | Z57: =IF(N57="","",N57*IFERROR(VLOOKUP($A57&"|Jul",Lists!$J:$L,2,FALSE),0)*IFERROR(VLOOKUP($A57&"|Jul",Lists!$J:$L,3,FALSE),0)) | AA57: =IF(O57="","",O57*IFERROR(VLOOKUP($A57&"|Aug",Lists!$J:$L,2,FALSE),0)*IFERROR(VLOOKUP($A57&"|Aug",Lists!$J:$L,3,FALSE),0)) | AB57: =IF(P57="","",P57*IFERROR(VLOOKUP($A57&"|Sep",Lists!$J:$L,2,FALSE),0)*IFERROR(VLOOKUP($A57&"|Sep",Lists!$J:$L,3,FALSE),0)) | AC57: =IF(Q57="","",Q57*IFERROR(VLOOKUP($A57&"|Oct",Lists!$J:$L,2,FALSE),0)*IFERROR(VLOOKUP($A57&"|Oct",Lists!$J:$L,3,FALSE),0)) | AD57: =IF(R57="","",R57*IFERROR(VLOOKUP($A57&"|Nov",Lists!$J:$L,2,FALSE),0)*IFERROR(VLOOKUP($A57&"|Nov",Lists!$J:$L,3,FALSE),0)) | AE57: =IF(S57="","",S57*IFERROR(VLOOKUP($A57&"|Dec",Lists!$J:$L,2,FALSE),0)*IFERROR(VLOOKUP($A57&"|Dec",Lists!$J:$L,3,FALSE),0))
T58: =IF($A58="","",VLOOKUP($A58,DevRateTable,3,FALSE)) | U58: =IF(I58="","",I58*IFERROR(VLOOKUP($A58&"|Feb",Lists!$J:$L,2,FALSE),0)*IFERROR(VLOOKUP($A58&"|Feb",Lists!$J:$L,3,FALSE),0)) | V58: =IF(J58="","",J58*IFERROR(VLOOKUP($A58&"|Mar",Lists!$J:$L,2,FALSE),0)*IFERROR(VLOOKUP($A58&"|Mar",Lists!$J:$L,3,FALSE),0)) | W58: =IF(K58="","",K58*IFERROR(VLOOKUP($A58&"|Apr",Lists!$J:$L,2,FALSE),0)*IFERROR(VLOOKUP($A58&"|Apr",Lists!$J:$L,3,FALSE),0)) | X58: =IF(L58="","",L58*IFERROR(VLOOKUP($A58&"|May",Lists!$J:$L,2,FALSE),0)*IFERROR(VLOOKUP($A58&"|May",Lists!$J:$L,3,FALSE),0)) | Y58: =IF(M58="","",M58*IFERROR(VLOOKUP($A58&"|Jun",Lists!$J:$L,2,FALSE),0)*IFERROR(VLOOKUP($A58&"|Jun",Lists!$J:$L,3,FALSE),0)) | Z58: =IF(N58="","",N58*IFERROR(VLOOKUP($A58&"|Jul",Lists!$J:$L,2,FALSE),0)*IFERROR(VLOOKUP($A58&"|Jul",Lists!$J:$L,3,FALSE),0)) | AA58: =IF(O58="","",O58*IFERROR(VLOOKUP($A58&"|Aug",Lists!$J:$L,2,FALSE),0)*IFERROR(VLOOKUP($A58&"|Aug",Lists!$J:$L,3,FALSE),0)) | AB58: =IF(P58="","",P58*IFERROR(VLOOKUP($A58&"|Sep",Lists!$J:$L,2,FALSE),0)*IFERROR(VLOOKUP($A58&"|Sep",Lists!$J:$L,3,FALSE),0)) | AC58: =IF(Q58="","",Q58*IFERROR(VLOOKUP($A58&"|Oct",Lists!$J:$L,2,FALSE),0)*IFERROR(VLOOKUP($A58&"|Oct",Lists!$J:$L,3,FALSE),0)) | AD58: =IF(R58="","",R58*IFERROR(VLOOKUP($A58&"|Nov",Lists!$J:$L,2,FALSE),0)*IFERROR(VLOOKUP($A58&"|Nov",Lists!$J:$L,3,FALSE),0)) | AE58: =IF(S58="","",S58*IFERROR(VLOOKUP($A58&"|Dec",Lists!$J:$L,2,FALSE),0)*IFERROR(VLOOKUP($A58&"|Dec",Lists!$J:$L,3,FALSE),0))
T59: =IF($A59="","",VLOOKUP($A59,DevRateTable,3,FALSE)) | U59: =IF(I59="","",I59*IFERROR(VLOOKUP($A59&"|Feb",Lists!$J:$L,2,FALSE),0)*IFERROR(VLOOKUP($A59&"|Feb",Lists!$J:$L,3,FALSE),0)) | V59: =IF(J59="","",J59*IFERROR(VLOOKUP($A59&"|Mar",Lists!$J:$L,2,FALSE),0)*IFERROR(VLOOKUP($A59&"|Mar",Lists!$J:$L,3,FALSE),0)) | W59: =IF(K59="","",K59*IFERROR(VLOOKUP($A59&"|Apr",Lists!$J:$L,2,FALSE),0)*IFERROR(VLOOKUP($A59&"|Apr",Lists!$J:$L,3,FALSE),0)) | X59: =IF(L59="","",L59*IFERROR(VLOOKUP($A59&"|May",Lists!$J:$L,2,FALSE),0)*IFERROR(VLOOKUP($A59&"|May",Lists!$J:$L,3,FALSE),0)) | Y59: =IF(M59="","",M59*IFERROR(VLOOKUP($A59&"|Jun",Lists!$J:$L,2,FALSE),0)*IFERROR(VLOOKUP($A59&"|Jun",Lists!$J:$L,3,FALSE),0)) | Z59: =IF(N59="","",N59*IFERROR(VLOOKUP($A59&"|Jul",Lists!$J:$L,2,FALSE),0)*IFERROR(VLOOKUP($A59&"|Jul",Lists!$J:$L,3,FALSE),0)) | AA59: =IF(O59="","",O59*IFERROR(VLOOKUP($A59&"|Aug",Lists!$J:$L,2,FALSE),0)*IFERROR(VLOOKUP($A59&"|Aug",Lists!$J:$L,3,FALSE),0)) | AB59: =IF(P59="","",P59*IFERROR(VLOOKUP($A59&"|Sep",Lists!$J:$L,2,FALSE),0)*IFERROR(VLOOKUP($A59&"|Sep",Lists!$J:$L,3,FALSE),0)) | AC59: =IF(Q59="","",Q59*IFERROR(VLOOKUP($A59&"|Oct",Lists!$J:$L,2,FALSE),0)*IFERROR(VLOOKUP($A59&"|Oct",Lists!$J:$L,3,FALSE),0)) | AD59: =IF(R59="","",R59*IFERROR(VLOOKUP($A59&"|Nov",Lists!$J:$L,2,FALSE),0)*IFERROR(VLOOKUP($A59&"|Nov",Lists!$J:$L,3,FALSE),0)) | AE59: =IF(S59="","",S59*IFERROR(VLOOKUP($A59&"|Dec",Lists!$J:$L,2,FALSE),0)*IFERROR(VLOOKUP($A59&"|Dec",Lists!$J:$L,3,FALSE),0))
T60: =IF($A60="","",VLOOKUP($A60,DevRateTable,3,FALSE)) | U60: =IF(I60="","",I60*IFERROR(VLOOKUP($A60&"|Feb",Lists!$J:$L,2,FALSE),0)*IFERROR(VLOOKUP($A60&"|Feb",Lists!$J:$L,3,FALSE),0)) | V60: =IF(J60="","",J60*IFERROR(VLOOKUP($A60&"|Mar",Lists!$J:$L,2,FALSE),0)*IFERROR(VLOOKUP($A60&"|Mar",Lists!$J:$L,3,FALSE),0)) | W60: =IF(K60="","",K60*IFERROR(VLOOKUP($A60&"|Apr",Lists!$J:$L,2,FALSE),0)*IFERROR(VLOOKUP($A60&"|Apr",Lists!$J:$L,3,FALSE),0)) | X60: =IF(L60="","",L60*IFERROR(VLOOKUP($A60&"|May",Lists!$J:$L,2,FALSE),0)*IFERROR(VLOOKUP($A60&"|May",Lists!$J:$L,3,FALSE),0)) | Y60: =IF(M60="","",M60*IFERROR(VLOOKUP($A60&"|Jun",Lists!$J:$L,2,FALSE),0)*IFERROR(VLOOKUP($A60&"|Jun",Lists!$J:$L,3,FALSE),0)) | Z60: =IF(N60="","",N60*IFERROR(VLOOKUP($A60&"|Jul",Lists!$J:$L,2,FALSE),0)*IFERROR(VLOOKUP($A60&"|Jul",Lists!$J:$L,3,FALSE),0)) | AA60: =IF(O60="","",O60*IFERROR(VLOOKUP($A60&"|Aug",Lists!$J:$L,2,FALSE),0)*IFERROR(VLOOKUP($A60&"|Aug",Lists!$J:$L,3,FALSE),0)) | AB60: =IF(P60="","",P60*IFERROR(VLOOKUP($A60&"|Sep",Lists!$J:$L,2,FALSE),0)*IFERROR(VLOOKUP($A60&"|Sep",Lists!$J:$L,3,FALSE),0)) | AC60: =IF(Q60="","",Q60*IFERROR(VLOOKUP($A60&"|Oct",Lists!$J:$L,2,FALSE),0)*IFERROR(VLOOKUP($A60&"|Oct",Lists!$J:$L,3,FALSE),0)) | AD60: =IF(R60="","",R60*IFERROR(VLOOKUP($A60&"|Nov",Lists!$J:$L,2,FALSE),0)*IFERROR(VLOOKUP($A60&"|Nov",Lists!$J:$L,3,FALSE),0)) | AE60: =IF(S60="","",S60*IFERROR(VLOOKUP($A60&"|Dec",Lists!$J:$L,2,FALSE),0)*IFERROR(VLOOKUP($A60&"|Dec",Lists!$J:$L,3,FALSE),0))
T61: =IF($A61="","",VLOOKUP($A61,DevRateTable,3,FALSE)) | U61: =IF(I61="","",I61*IFERROR(VLOOKUP($A61&"|Feb",Lists!$J:$L,2,FALSE),0)*IFERROR(VLOOKUP($A61&"|Feb",Lists!$J:$L,3,FALSE),0)) | V61: =IF(J61="","",J61*IFERROR(VLOOKUP($A61&"|Mar",Lists!$J:$L,2,FALSE),0)*IFERROR(VLOOKUP($A61&"|Mar",Lists!$J:$L,3,FALSE),0)) | W61: =IF(K61="","",K61*IFERROR(VLOOKUP($A61&"|Apr",Lists!$J:$L,2,FALSE),0)*IFERROR(VLOOKUP($A61&"|Apr",Lists!$J:$L,3,FALSE),0)) | X61: =IF(L61="","",L61*IFERROR(VLOOKUP($A61&"|May",Lists!$J:$L,2,FALSE),0)*IFERROR(VLOOKUP($A61&"|May",Lists!$J:$L,3,FALSE),0)) | Y61: =IF(M61="","",M61*IFERROR(VLOOKUP($A61&"|Jun",Lists!$J:$L,2,FALSE),0)*IFERROR(VLOOKUP($A61&"|Jun",Lists!$J:$L,3,FALSE),0)) | Z61: =IF(N61="","",N61*IFERROR(VLOOKUP($A61&"|Jul",Lists!$J:$L,2,FALSE),0)*IFERROR(VLOOKUP($A61&"|Jul",Lists!$J:$L,3,FALSE),0)) | AA61: =IF(O61="","",O61*IFERROR(VLOOKUP($A61&"|Aug",Lists!$J:$L,2,FALSE),0)*IFERROR(VLOOKUP($A61&"|Aug",Lists!$J:$L,3,FALSE),0)) | AB61: =IF(P61="","",P61*IFERROR(VLOOKUP($A61&"|Sep",Lists!$J:$L,2,FALSE),0)*IFERROR(VLOOKUP($A61&"|Sep",Lists!$J:$L,3,FALSE),0)) | AC61: =IF(Q61="","",Q61*IFERROR(VLOOKUP($A61&"|Oct",Lists!$J:$L,2,FALSE),0)*IFERROR(VLOOKUP($A61&"|Oct",Lists!$J:$L,3,FALSE),0)) | AD61: =IF(R61="","",R61*IFERROR(VLOOKUP($A61&"|Nov",Lists!$J:$L,2,FALSE),0)*IFERROR(VLOOKUP($A61&"|Nov",Lists!$J:$L,3,FALSE),0)) | AE61: =IF(S61="","",S61*IFERROR(VLOOKUP($A61&"|Dec",Lists!$J:$L,2,FALSE),0)*IFERROR(VLOOKUP($A61&"|Dec",Lists!$J:$L,3,FALSE),0))
T62: =IF($A62="","",VLOOKUP($A62,DevRateTable,3,FALSE)) | U62: =IF(I62="","",I62*IFERROR(VLOOKUP($A62&"|Feb",Lists!$J:$L,2,FALSE),0)*IFERROR(VLOOKUP($A62&"|Feb",Lists!$J:$L,3,FALSE),0)) | V62: =IF(J62="","",J62*IFERROR(VLOOKUP($A62&"|Mar",Lists!$J:$L,2,FALSE),0)*IFERROR(VLOOKUP($A62&"|Mar",Lists!$J:$L,3,FALSE),0)) | W62: =IF(K62="","",K62*IFERROR(VLOOKUP($A62&"|Apr",Lists!$J:$L,2,FALSE),0)*IFERROR(VLOOKUP($A62&"|Apr",Lists!$J:$L,3,FALSE),0)) | X62: =IF(L62="","",L62*IFERROR(VLOOKUP($A62&"|May",Lists!$J:$L,2,FALSE),0)*IFERROR(VLOOKUP($A62&"|May",Lists!$J:$L,3,FALSE),0)) | Y62: =IF(M62="","",M62*IFERROR(VLOOKUP($A62&"|Jun",Lists!$J:$L,2,FALSE),0)*IFERROR(VLOOKUP($A62&"|Jun",Lists!$J:$L,3,FALSE),0)) | Z62: =IF(N62="","",N62*IFERROR(VLOOKUP($A62&"|Jul",Lists!$J:$L,2,FALSE),0)*IFERROR(VLOOKUP($A62&"|Jul",Lists!$J:$L,3,FALSE),0)) | AA62: =IF(O62="","",O62*IFERROR(VLOOKUP($A62&"|Aug",Lists!$J:$L,2,FALSE),0)*IFERROR(VLOOKUP($A62&"|Aug",Lists!$J:$L,3,FALSE),0)) | AB62: =IF(P62="","",P62*IFERROR(VLOOKUP($A62&"|Sep",Lists!$J:$L,2,FALSE),0)*IFERROR(VLOOKUP($A62&"|Sep",Lists!$J:$L,3,FALSE),0)) | AC62: =IF(Q62="","",Q62*IFERROR(VLOOKUP($A62&"|Oct",Lists!$J:$L,2,FALSE),0)*IFERROR(VLOOKUP($A62&"|Oct",Lists!$J:$L,3,FALSE),0)) | AD62: =IF(R62="","",R62*IFERROR(VLOOKUP($A62&"|Nov",Lists!$J:$L,2,FALSE),0)*IFERROR(VLOOKUP($A62&"|Nov",Lists!$J:$L,3,FALSE),0)) | AE62: =IF(S62="","",S62*IFERROR(VLOOKUP($A62&"|Dec",Lists!$J:$L,2,FALSE),0)*IFERROR(VLOOKUP($A62&"|Dec",Lists!$J:$L,3,FALSE),0))
T63: =IF($A63="","",VLOOKUP($A63,DevRateTable,3,FALSE)) | U63: =IF(I63="","",I63*IFERROR(VLOOKUP($A63&"|Feb",Lists!$J:$L,2,FALSE),0)*IFERROR(VLOOKUP($A63&"|Feb",Lists!$J:$L,3,FALSE),0)) | V63: =IF(J63="","",J63*IFERROR(VLOOKUP($A63&"|Mar",Lists!$J:$L,2,FALSE),0)*IFERROR(VLOOKUP($A63&"|Mar",Lists!$J:$L,3,FALSE),0)) | W63: =IF(K63="","",K63*IFERROR(VLOOKUP($A63&"|Apr",Lists!$J:$L,2,FALSE),0)*IFERROR(VLOOKUP($A63&"|Apr",Lists!$J:$L,3,FALSE),0)) | X63: =IF(L63="","",L63*IFERROR(VLOOKUP($A63&"|May",Lists!$J:$L,2,FALSE),0)*IFERROR(VLOOKUP($A63&"|May",Lists!$J:$L,3,FALSE),0)) | Y63: =IF(M63="","",M63*IFERROR(VLOOKUP($A63&"|Jun",Lists!$J:$L,2,FALSE),0)*IFERROR(VLOOKUP($A63&"|Jun",Lists!$J:$L,3,FALSE),0)) | Z63: =IF(N63="","",N63*IFERROR(VLOOKUP($A63&"|Jul",Lists!$J:$L,2,FALSE),0)*IFERROR(VLOOKUP($A63&"|Jul",Lists!$J:$L,3,FALSE),0)) | AA63: =IF(O63="","",O63*IFERROR(VLOOKUP($A63&"|Aug",Lists!$J:$L,2,FALSE),0)*IFERROR(VLOOKUP($A63&"|Aug",Lists!$J:$L,3,FALSE),0)) | AB63: =IF(P63="","",P63*IFERROR(VLOOKUP($A63&"|Sep",Lists!$J:$L,2,FALSE),0)*IFERROR(VLOOKUP($A63&"|Sep",Lists!$J:$L,3,FALSE),0)) | AC63: =IF(Q63="","",Q63*IFERROR(VLOOKUP($A63&"|Oct",Lists!$J:$L,2,FALSE),0)*IFERROR(VLOOKUP($A63&"|Oct",Lists!$J:$L,3,FALSE),0)) | AD63: =IF(R63="","",R63*IFERROR(VLOOKUP($A63&"|Nov",Lists!$J:$L,2,FALSE),0)*IFERROR(VLOOKUP($A63&"|Nov",Lists!$J:$L,3,FALSE),0)) | AE63: =IF(S63="","",S63*IFERROR(VLOOKUP($A63&"|Dec",Lists!$J:$L,2,FALSE),0)*IFERROR(VLOOKUP($A63&"|Dec",Lists!$J:$L,3,FALSE),0))
T64: =IF($A64="","",VLOOKUP($A64,DevRateTable,3,FALSE)) | U64: =IF(I64="","",I64*IFERROR(VLOOKUP($A64&"|Feb",Lists!$J:$L,2,FALSE),0)*IFERROR(VLOOKUP($A64&"|Feb",Lists!$J:$L,3,FALSE),0)) | V64: =IF(J64="","",J64*IFERROR(VLOOKUP($A64&"|Mar",Lists!$J:$L,2,FALSE),0)*IFERROR(VLOOKUP($A64&"|Mar",Lists!$J:$L,3,FALSE),0)) | W64: =IF(K64="","",K64*IFERROR(VLOOKUP($A64&"|Apr",Lists!$J:$L,2,FALSE),0)*IFERROR(VLOOKUP($A64&"|Apr",Lists!$J:$L,3,FALSE),0)) | X64: =IF(L64="","",L64*IFERROR(VLOOKUP($A64&"|May",Lists!$J:$L,2,FALSE),0)*IFERROR(VLOOKUP($A64&"|May",Lists!$J:$L,3,FALSE),0)) | Y64: =IF(M64="","",M64*IFERROR(VLOOKUP($A64&"|Jun",Lists!$J:$L,2,FALSE),0)*IFERROR(VLOOKUP($A64&"|Jun",Lists!$J:$L,3,FALSE),0)) | Z64: =IF(N64="","",N64*IFERROR(VLOOKUP($A64&"|Jul",Lists!$J:$L,2,FALSE),0)*IFERROR(VLOOKUP($A64&"|Jul",Lists!$J:$L,3,FALSE),0)) | AA64: =IF(O64="","",O64*IFERROR(VLOOKUP($A64&"|Aug",Lists!$J:$L,2,FALSE),0)*IFERROR(VLOOKUP($A64&"|Aug",Lists!$J:$L,3,FALSE),0)) | AB64: =IF(P64="","",P64*IFERROR(VLOOKUP($A64&"|Sep",Lists!$J:$L,2,FALSE),0)*IFERROR(VLOOKUP($A64&"|Sep",Lists!$J:$L,3,FALSE),0)) | AC64: =IF(Q64="","",Q64*IFERROR(VLOOKUP($A64&"|Oct",Lists!$J:$L,2,FALSE),0)*IFERROR(VLOOKUP($A64&"|Oct",Lists!$J:$L,3,FALSE),0)) | AD64: =IF(R64="","",R64*IFERROR(VLOOKUP($A64&"|Nov",Lists!$J:$L,2,FALSE),0)*IFERROR(VLOOKUP($A64&"|Nov",Lists!$J:$L,3,FALSE),0)) | AE64: =IF(S64="","",S64*IFERROR(VLOOKUP($A64&"|Dec",Lists!$J:$L,2,FALSE),0)*IFERROR(VLOOKUP($A64&"|Dec",Lists!$J:$L,3,FALSE),0))
